return { { ["y"] = -2, ["x"] = -6, ["name"] = "default:dirt", ["z"] = -2, ["meta"] = { ["inventory"] = {  }, ["fields"] = {  } }, ["param2"] = 0, ["param1"] = 0 }, { ["y"] = -2, ["x"] = -6, ["name"] = "default:dirt", ["z"] = -1, ["meta"] = { ["inventory"] = {  }, ["fields"] = {  } }, ["param2"] = 0, ["param1"] = 0 }, { ["y"] = -2, ["x"] = -6, ["name"] = "default:dirt", ["z"] = 0, ["meta"] = { ["inventory"] = {  }, ["fields"] = {  } }, ["param2"] = 0, ["param1"] = 0 }, { ["y"] = -2, ["x"] = -6, ["name"] = "default:dirt", ["z"] = 1, ["meta"] = { ["inventory"] = {  }, ["fields"] = {  } }, ["param2"] = 0, ["param1"] = 0 }, { ["y"] = -1, ["x"] = -6, ["name"] = "default:dirt", ["z"] = -2, ["meta"] = { ["inventory"] = {  }, ["fields"] = {  } }, ["param2"] = 0, ["param1"] = 0 }, { ["y"] = -1, ["x"] = -6, ["name"] = "default:dirt", ["z"] = -1, ["meta"] = { ["inventory"] = {  }, ["fields"] = {  } }, ["param2"] = 0, ["param1"] = 0 }, { ["y"] = -1, ["x"] = -6, ["name"] = "default:dirt", ["z"] = 0, ["meta"] = { ["inventory"] = {  }, ["fields"] = {  } }, ["param2"] = 0, ["param1"] = 0 }, { ["y"] = -1, ["x"] = -6, ["name"] = "default:dirt", ["z"] = 1, ["meta"] = { ["inventory"] = {  }, ["fields"] = {  } }, ["param2"] = 0, ["param1"] = 0 }, { ["y"] = 0, ["x"] = -6, ["name"] = "default:dirt", ["z"] = -2, ["meta"] = { ["inventory"] = {  }, ["fields"] = {  } }, ["param2"] = 0, ["param1"] = 0 }, { ["y"] = 0, ["x"] = -6, ["name"] = "default:dirt", ["z"] = -1, ["meta"] = { ["inventory"] = {  }, ["fields"] = {  } }, ["param2"] = 0, ["param1"] = 0 }, { ["y"] = 0, ["x"] = -6, ["name"] = "default:dirt", ["z"] = 0, ["meta"] = { ["inventory"] = {  }, ["fields"] = {  } }, ["param2"] = 0, ["param1"] = 0 }, { ["y"] = 0, ["x"] = -6, ["name"] = "default:dirt", ["z"] = 1, ["meta"] = { ["inventory"] = {  }, ["fields"] = {  } }, ["param2"] = 0, ["param1"] = 0 }, { ["y"] = 1, ["x"] = -6, ["name"] = "default:dirt", ["z"] = -2, ["meta"] = { ["inventory"] = {  }, ["fields"] = {  } }, ["param2"] = 0, ["param1"] = 0 }, { ["y"] = 1, ["x"] = -6, ["name"] = "default:dirt", ["z"] = -1, ["meta"] = { ["inventory"] = {  }, ["fields"] = {  } }, ["param2"] = 0, ["param1"] = 0 }, { ["y"] = 1, ["x"] = -6, ["name"] = "default:dirt", ["z"] = 0, ["meta"] = { ["inventory"] = {  }, ["fields"] = {  } }, ["param2"] = 0, ["param1"] = 0 }, { ["y"] = 1, ["x"] = -6, ["name"] = "default:dirt", ["z"] = 1, ["meta"] = { ["inventory"] = {  }, ["fields"] = {  } }, ["param2"] = 0, ["param1"] = 0 }, { ["y"] = -3, ["x"] = -5, ["name"] = "default:dirt", ["z"] = -3, ["meta"] = { ["inventory"] = {  }, ["fields"] = {  } }, ["param2"] = 0, ["param1"] = 0 }, { ["y"] = -3, ["x"] = -5, ["name"] = "default:dirt", ["z"] = -2, ["meta"] = { ["inventory"] = {  }, ["fields"] = {  } }, ["param2"] = 0, ["param1"] = 0 }, { ["y"] = -3, ["x"] = -5, ["name"] = "default:dirt", ["z"] = -1, ["meta"] = { ["inventory"] = {  }, ["fields"] = {  } }, ["param2"] = 0, ["param1"] = 0 }, { ["y"] = -3, ["x"] = -5, ["name"] = "default:dirt", ["z"] = 0, ["meta"] = { ["inventory"] = {  }, ["fields"] = {  } }, ["param2"] = 0, ["param1"] = 0 }, { ["y"] = -3, ["x"] = -5, ["name"] = "default:dirt", ["z"] = 1, ["meta"] = { ["inventory"] = {  }, ["fields"] = {  } }, ["param2"] = 0, ["param1"] = 0 }, { ["y"] = -3, ["x"] = -5, ["name"] = "default:dirt", ["z"] = 2, ["meta"] = { ["inventory"] = {  }, ["fields"] = {  } }, ["param2"] = 0, ["param1"] = 0 }, { ["y"] = -3, ["x"] = -5, ["name"] = "default:dirt", ["z"] = -4, ["meta"] = { ["inventory"] = {  }, ["fields"] = {  } }, ["param2"] = 0, ["param1"] = 0 }, { ["y"] = -3, ["x"] = -5, ["name"] = "default:dirt", ["z"] = 3, ["meta"] = { ["inventory"] = {  }, ["fields"] = {  } }, ["param2"] = 0, ["param1"] = 0 }, { ["y"] = -2, ["x"] = -5, ["name"] = "default:dirt", ["z"] = -3, ["meta"] = { ["inventory"] = {  }, ["fields"] = {  } }, ["param2"] = 0, ["param1"] = 0 }, { ["y"] = -2, ["x"] = -5, ["name"] = "default:dirt", ["z"] = -2, ["meta"] = { ["inventory"] = {  }, ["fields"] = {  } }, ["param2"] = 0, ["param1"] = 0 }, { ["y"] = -2, ["x"] = -5, ["name"] = "default:dirt", ["z"] = -1, ["meta"] = { ["inventory"] = {  }, ["fields"] = {  } }, ["param2"] = 0, ["param1"] = 0 }, { ["y"] = -2, ["x"] = -5, ["name"] = "default:dirt", ["z"] = 0, ["meta"] = { ["inventory"] = {  }, ["fields"] = {  } }, ["param2"] = 0, ["param1"] = 0 }, { ["y"] = -2, ["x"] = -5, ["name"] = "default:dirt", ["z"] = 1, ["meta"] = { ["inventory"] = {  }, ["fields"] = {  } }, ["param2"] = 0, ["param1"] = 0 }, { ["y"] = -2, ["x"] = -5, ["name"] = "default:dirt", ["z"] = 2, ["meta"] = { ["inventory"] = {  }, ["fields"] = {  } }, ["param2"] = 0, ["param1"] = 0 }, { ["y"] = -2, ["x"] = -5, ["name"] = "default:dirt", ["z"] = -4, ["meta"] = { ["inventory"] = {  }, ["fields"] = {  } }, ["param2"] = 0, ["param1"] = 0 }, { ["y"] = -2, ["x"] = -5, ["name"] = "default:dirt", ["z"] = 3, ["meta"] = { ["inventory"] = {  }, ["fields"] = {  } }, ["param2"] = 0, ["param1"] = 0 }, { ["y"] = -1, ["x"] = -5, ["name"] = "default:dirt", ["z"] = -3, ["meta"] = { ["inventory"] = {  }, ["fields"] = {  } }, ["param2"] = 0, ["param1"] = 0 }, { ["y"] = -1, ["x"] = -5, ["name"] = "default:dirt", ["z"] = -2, ["meta"] = { ["inventory"] = {  }, ["fields"] = {  } }, ["param2"] = 0, ["param1"] = 0 }, { ["y"] = -1, ["x"] = -5, ["name"] = "default:dirt", ["z"] = -1, ["meta"] = { ["inventory"] = {  }, ["fields"] = {  } }, ["param2"] = 0, ["param1"] = 0 }, { ["y"] = -1, ["x"] = -5, ["name"] = "default:dirt", ["z"] = 0, ["meta"] = { ["inventory"] = {  }, ["fields"] = {  } }, ["param2"] = 0, ["param1"] = 0 }, { ["y"] = -1, ["x"] = -5, ["name"] = "default:dirt", ["z"] = 1, ["meta"] = { ["inventory"] = {  }, ["fields"] = {  } }, ["param2"] = 0, ["param1"] = 0 }, { ["y"] = -1, ["x"] = -5, ["name"] = "default:dirt", ["z"] = 2, ["meta"] = { ["inventory"] = {  }, ["fields"] = {  } }, ["param2"] = 0, ["param1"] = 0 }, { ["y"] = -1, ["x"] = -5, ["name"] = "default:dirt", ["z"] = -4, ["meta"] = { ["inventory"] = {  }, ["fields"] = {  } }, ["param2"] = 0, ["param1"] = 0 }, { ["y"] = -1, ["x"] = -5, ["name"] = "default:dirt", ["z"] = 3, ["meta"] = { ["inventory"] = {  }, ["fields"] = {  } }, ["param2"] = 0, ["param1"] = 0 }, { ["y"] = 0, ["x"] = -5, ["name"] = "default:dirt", ["z"] = -3, ["meta"] = { ["inventory"] = {  }, ["fields"] = {  } }, ["param2"] = 0, ["param1"] = 0 }, { ["y"] = 0, ["x"] = -5, ["name"] = "default:dirt", ["z"] = -2, ["meta"] = { ["inventory"] = {  }, ["fields"] = {  } }, ["param2"] = 0, ["param1"] = 0 }, { ["y"] = 0, ["x"] = -5, ["name"] = "default:dirt", ["z"] = -1, ["meta"] = { ["inventory"] = {  }, ["fields"] = {  } }, ["param2"] = 0, ["param1"] = 0 }, { ["y"] = 0, ["x"] = -5, ["name"] = "default:dirt", ["z"] = 0, ["meta"] = { ["inventory"] = {  }, ["fields"] = {  } }, ["param2"] = 0, ["param1"] = 0 }, { ["y"] = 0, ["x"] = -5, ["name"] = "default:dirt", ["z"] = 1, ["meta"] = { ["inventory"] = {  }, ["fields"] = {  } }, ["param2"] = 0, ["param1"] = 0 }, { ["y"] = 0, ["x"] = -5, ["name"] = "default:dirt", ["z"] = 2, ["meta"] = { ["inventory"] = {  }, ["fields"] = {  } }, ["param2"] = 0, ["param1"] = 0 }, { ["y"] = 0, ["x"] = -5, ["name"] = "default:dirt", ["z"] = -4, ["meta"] = { ["inventory"] = {  }, ["fields"] = {  } }, ["param2"] = 0, ["param1"] = 0 }, { ["y"] = 0, ["x"] = -5, ["name"] = "default:dirt", ["z"] = 3, ["meta"] = { ["inventory"] = {  }, ["fields"] = {  } }, ["param2"] = 0, ["param1"] = 0 }, { ["y"] = 1, ["x"] = -5, ["name"] = "default:dirt", ["z"] = -3, ["meta"] = { ["inventory"] = {  }, ["fields"] = {  } }, ["param2"] = 0, ["param1"] = 0 }, { ["y"] = 1, ["x"] = -5, ["name"] = "default:dirt", ["z"] = -2, ["meta"] = { ["inventory"] = {  }, ["fields"] = {  } }, ["param2"] = 0, ["param1"] = 0 }, { ["y"] = 1, ["x"] = -5, ["name"] = "default:dirt", ["z"] = -1, ["meta"] = { ["inventory"] = {  }, ["fields"] = {  } }, ["param2"] = 0, ["param1"] = 0 }, { ["y"] = 1, ["x"] = -5, ["name"] = "default:dirt", ["z"] = 0, ["meta"] = { ["inventory"] = {  }, ["fields"] = {  } }, ["param2"] = 0, ["param1"] = 0 }, { ["y"] = 1, ["x"] = -5, ["name"] = "default:dirt", ["z"] = 1, ["meta"] = { ["inventory"] = {  }, ["fields"] = {  } }, ["param2"] = 0, ["param1"] = 0 }, { ["y"] = 1, ["x"] = -5, ["name"] = "default:dirt", ["z"] = 2, ["meta"] = { ["inventory"] = {  }, ["fields"] = {  } }, ["param2"] = 0, ["param1"] = 0 }, { ["y"] = 1, ["x"] = -5, ["name"] = "default:dirt", ["z"] = -4, ["meta"] = { ["inventory"] = {  }, ["fields"] = {  } }, ["param2"] = 0, ["param1"] = 0 }, { ["y"] = 1, ["x"] = -5, ["name"] = "default:dirt", ["z"] = 3, ["meta"] = { ["inventory"] = {  }, ["fields"] = {  } }, ["param2"] = 0, ["param1"] = 0 }, { ["y"] = 2, ["x"] = -5, ["name"] = "default:dirt", ["z"] = -3, ["meta"] = { ["inventory"] = {  }, ["fields"] = {  } }, ["param2"] = 0, ["param1"] = 0 }, { ["y"] = 2, ["x"] = -5, ["name"] = "default:dirt", ["z"] = -2, ["meta"] = { ["inventory"] = {  }, ["fields"] = {  } }, ["param2"] = 0, ["param1"] = 0 }, { ["y"] = 2, ["x"] = -5, ["name"] = "default:dirt", ["z"] = -1, ["meta"] = { ["inventory"] = {  }, ["fields"] = {  } }, ["param2"] = 0, ["param1"] = 0 }, { ["y"] = 2, ["x"] = -5, ["name"] = "default:dirt", ["z"] = 0, ["meta"] = { ["inventory"] = {  }, ["fields"] = {  } }, ["param2"] = 0, ["param1"] = 0 }, { ["y"] = 2, ["x"] = -5, ["name"] = "default:dirt", ["z"] = 1, ["meta"] = { ["inventory"] = {  }, ["fields"] = {  } }, ["param2"] = 0, ["param1"] = 0 }, { ["y"] = 2, ["x"] = -5, ["name"] = "default:dirt", ["z"] = 2, ["meta"] = { ["inventory"] = {  }, ["fields"] = {  } }, ["param2"] = 0, ["param1"] = 0 }, { ["y"] = 2, ["x"] = -5, ["name"] = "default:dirt", ["z"] = -4, ["meta"] = { ["inventory"] = {  }, ["fields"] = {  } }, ["param2"] = 0, ["param1"] = 0 }, { ["y"] = 2, ["x"] = -5, ["name"] = "default:dirt", ["z"] = 3, ["meta"] = { ["inventory"] = {  }, ["fields"] = {  } }, ["param2"] = 0, ["param1"] = 0 }, { ["y"] = -4, ["x"] = -5, ["name"] = "default:dirt", ["z"] = -3, ["meta"] = { ["inventory"] = {  }, ["fields"] = {  } }, ["param2"] = 0, ["param1"] = 0 }, { ["y"] = -4, ["x"] = -5, ["name"] = "default:dirt", ["z"] = -2, ["meta"] = { ["inventory"] = {  }, ["fields"] = {  } }, ["param2"] = 0, ["param1"] = 0 }, { ["y"] = -4, ["x"] = -5, ["name"] = "default:dirt", ["z"] = -1, ["meta"] = { ["inventory"] = {  }, ["fields"] = {  } }, ["param2"] = 0, ["param1"] = 0 }, { ["y"] = -4, ["x"] = -5, ["name"] = "default:dirt", ["z"] = 0, ["meta"] = { ["inventory"] = {  }, ["fields"] = {  } }, ["param2"] = 0, ["param1"] = 0 }, { ["y"] = -4, ["x"] = -5, ["name"] = "default:dirt", ["z"] = 1, ["meta"] = { ["inventory"] = {  }, ["fields"] = {  } }, ["param2"] = 0, ["param1"] = 0 }, { ["y"] = -4, ["x"] = -5, ["name"] = "default:dirt", ["z"] = 2, ["meta"] = { ["inventory"] = {  }, ["fields"] = {  } }, ["param2"] = 0, ["param1"] = 0 }, { ["y"] = -4, ["x"] = -5, ["name"] = "default:dirt", ["z"] = -4, ["meta"] = { ["inventory"] = {  }, ["fields"] = {  } }, ["param2"] = 0, ["param1"] = 0 }, { ["y"] = -4, ["x"] = -5, ["name"] = "default:dirt", ["z"] = 3, ["meta"] = { ["inventory"] = {  }, ["fields"] = {  } }, ["param2"] = 0, ["param1"] = 0 }, { ["y"] = 3, ["x"] = -5, ["name"] = "default:dirt", ["z"] = -3, ["meta"] = { ["inventory"] = {  }, ["fields"] = {  } }, ["param2"] = 0, ["param1"] = 0 }, { ["y"] = 3, ["x"] = -5, ["name"] = "default:dirt", ["z"] = -2, ["meta"] = { ["inventory"] = {  }, ["fields"] = {  } }, ["param2"] = 0, ["param1"] = 0 }, { ["y"] = 3, ["x"] = -5, ["name"] = "default:dirt", ["z"] = -1, ["meta"] = { ["inventory"] = {  }, ["fields"] = {  } }, ["param2"] = 0, ["param1"] = 0 }, { ["y"] = 3, ["x"] = -5, ["name"] = "default:dirt", ["z"] = 0, ["meta"] = { ["inventory"] = {  }, ["fields"] = {  } }, ["param2"] = 0, ["param1"] = 0 }, { ["y"] = 3, ["x"] = -5, ["name"] = "default:dirt", ["z"] = 1, ["meta"] = { ["inventory"] = {  }, ["fields"] = {  } }, ["param2"] = 0, ["param1"] = 0 }, { ["y"] = 3, ["x"] = -5, ["name"] = "default:dirt", ["z"] = 2, ["meta"] = { ["inventory"] = {  }, ["fields"] = {  } }, ["param2"] = 0, ["param1"] = 0 }, { ["y"] = 3, ["x"] = -5, ["name"] = "default:dirt", ["z"] = -4, ["meta"] = { ["inventory"] = {  }, ["fields"] = {  } }, ["param2"] = 0, ["param1"] = 0 }, { ["y"] = 3, ["x"] = -5, ["name"] = "default:dirt", ["z"] = 3, ["meta"] = { ["inventory"] = {  }, ["fields"] = {  } }, ["param2"] = 0, ["param1"] = 0 }, { ["y"] = -4, ["x"] = -4, ["name"] = "default:dirt", ["z"] = -4, ["meta"] = { ["inventory"] = {  }, ["fields"] = {  } }, ["param2"] = 0, ["param1"] = 0 }, { ["y"] = -4, ["x"] = -4, ["name"] = "default:dirt", ["z"] = -3, ["meta"] = { ["inventory"] = {  }, ["fields"] = {  } }, ["param2"] = 0, ["param1"] = 0 }, { ["y"] = -4, ["x"] = -4, ["name"] = "default:dirt", ["z"] = -2, ["meta"] = { ["inventory"] = {  }, ["fields"] = {  } }, ["param2"] = 0, ["param1"] = 0 }, { ["y"] = -4, ["x"] = -4, ["name"] = "default:dirt", ["z"] = -1, ["meta"] = { ["inventory"] = {  }, ["fields"] = {  } }, ["param2"] = 0, ["param1"] = 0 }, { ["y"] = -4, ["x"] = -4, ["name"] = "default:dirt", ["z"] = 0, ["meta"] = { ["inventory"] = {  }, ["fields"] = {  } }, ["param2"] = 0, ["param1"] = 0 }, { ["y"] = -4, ["x"] = -4, ["name"] = "default:dirt", ["z"] = 1, ["meta"] = { ["inventory"] = {  }, ["fields"] = {  } }, ["param2"] = 0, ["param1"] = 0 }, { ["y"] = -4, ["x"] = -4, ["name"] = "default:dirt", ["z"] = 2, ["meta"] = { ["inventory"] = {  }, ["fields"] = {  } }, ["param2"] = 0, ["param1"] = 0 }, { ["y"] = -4, ["x"] = -4, ["name"] = "default:dirt", ["z"] = 3, ["meta"] = { ["inventory"] = {  }, ["fields"] = {  } }, ["param2"] = 0, ["param1"] = 0 }, { ["y"] = -4, ["x"] = -4, ["name"] = "default:dirt", ["z"] = 4, ["meta"] = { ["inventory"] = {  }, ["fields"] = {  } }, ["param2"] = 0, ["param1"] = 0 }, { ["y"] = -4, ["x"] = -4, ["name"] = "default:dirt", ["z"] = -5, ["meta"] = { ["inventory"] = {  }, ["fields"] = {  } }, ["param2"] = 0, ["param1"] = 0 }, { ["y"] = -3, ["x"] = -4, ["name"] = "default:dirt", ["z"] = -4, ["meta"] = { ["inventory"] = {  }, ["fields"] = {  } }, ["param2"] = 0, ["param1"] = 0 }, { ["y"] = -3, ["x"] = -4, ["name"] = "default:dirt", ["z"] = -3, ["meta"] = { ["inventory"] = {  }, ["fields"] = {  } }, ["param2"] = 0, ["param1"] = 0 }, { ["y"] = -3, ["x"] = -4, ["name"] = "default:dirt", ["z"] = -2, ["meta"] = { ["inventory"] = {  }, ["fields"] = {  } }, ["param2"] = 0, ["param1"] = 0 }, { ["y"] = -3, ["x"] = -4, ["name"] = "default:dirt", ["z"] = -1, ["meta"] = { ["inventory"] = {  }, ["fields"] = {  } }, ["param2"] = 0, ["param1"] = 0 }, { ["y"] = -3, ["x"] = -4, ["name"] = "default:dirt", ["z"] = 0, ["meta"] = { ["inventory"] = {  }, ["fields"] = {  } }, ["param2"] = 0, ["param1"] = 0 }, { ["y"] = -3, ["x"] = -4, ["name"] = "default:dirt", ["z"] = 1, ["meta"] = { ["inventory"] = {  }, ["fields"] = {  } }, ["param2"] = 0, ["param1"] = 0 }, { ["y"] = -3, ["x"] = -4, ["name"] = "default:dirt", ["z"] = 2, ["meta"] = { ["inventory"] = {  }, ["fields"] = {  } }, ["param2"] = 0, ["param1"] = 0 }, { ["y"] = -3, ["x"] = -4, ["name"] = "default:dirt", ["z"] = 3, ["meta"] = { ["inventory"] = {  }, ["fields"] = {  } }, ["param2"] = 0, ["param1"] = 0 }, { ["y"] = -3, ["x"] = -4, ["name"] = "default:dirt", ["z"] = 4, ["meta"] = { ["inventory"] = {  }, ["fields"] = {  } }, ["param2"] = 0, ["param1"] = 0 }, { ["y"] = -3, ["x"] = -4, ["name"] = "default:dirt", ["z"] = -5, ["meta"] = { ["inventory"] = {  }, ["fields"] = {  } }, ["param2"] = 0, ["param1"] = 0 }, { ["y"] = -2, ["x"] = -4, ["name"] = "default:dirt", ["z"] = -4, ["meta"] = { ["inventory"] = {  }, ["fields"] = {  } }, ["param2"] = 0, ["param1"] = 0 }, { ["y"] = -2, ["x"] = -4, ["name"] = "default:dirt", ["z"] = -3, ["meta"] = { ["inventory"] = {  }, ["fields"] = {  } }, ["param2"] = 0, ["param1"] = 0 }, { ["y"] = -2, ["x"] = -4, ["name"] = "default:dirt", ["z"] = -2, ["meta"] = { ["inventory"] = {  }, ["fields"] = {  } }, ["param2"] = 0, ["param1"] = 0 }, { ["y"] = -2, ["x"] = -4, ["name"] = "default:dirt", ["z"] = -1, ["meta"] = { ["inventory"] = {  }, ["fields"] = {  } }, ["param2"] = 0, ["param1"] = 0 }, { ["y"] = -2, ["x"] = -4, ["name"] = "default:dirt", ["z"] = 0, ["meta"] = { ["inventory"] = {  }, ["fields"] = {  } }, ["param2"] = 0, ["param1"] = 0 }, { ["y"] = -2, ["x"] = -4, ["name"] = "default:dirt", ["z"] = 1, ["meta"] = { ["inventory"] = {  }, ["fields"] = {  } }, ["param2"] = 0, ["param1"] = 0 }, { ["y"] = -2, ["x"] = -4, ["name"] = "default:dirt", ["z"] = 2, ["meta"] = { ["inventory"] = {  }, ["fields"] = {  } }, ["param2"] = 0, ["param1"] = 0 }, { ["y"] = -2, ["x"] = -4, ["name"] = "default:dirt", ["z"] = 3, ["meta"] = { ["inventory"] = {  }, ["fields"] = {  } }, ["param2"] = 0, ["param1"] = 0 }, { ["y"] = -2, ["x"] = -4, ["name"] = "default:dirt", ["z"] = 4, ["meta"] = { ["inventory"] = {  }, ["fields"] = {  } }, ["param2"] = 0, ["param1"] = 0 }, { ["y"] = -2, ["x"] = -4, ["name"] = "default:dirt", ["z"] = -5, ["meta"] = { ["inventory"] = {  }, ["fields"] = {  } }, ["param2"] = 0, ["param1"] = 0 }, { ["y"] = -1, ["x"] = -4, ["name"] = "default:dirt", ["z"] = -4, ["meta"] = { ["inventory"] = {  }, ["fields"] = {  } }, ["param2"] = 0, ["param1"] = 0 }, { ["y"] = -1, ["x"] = -4, ["name"] = "default:dirt", ["z"] = -3, ["meta"] = { ["inventory"] = {  }, ["fields"] = {  } }, ["param2"] = 0, ["param1"] = 0 }, { ["y"] = -1, ["x"] = -4, ["name"] = "default:dirt", ["z"] = -2, ["meta"] = { ["inventory"] = {  }, ["fields"] = {  } }, ["param2"] = 0, ["param1"] = 0 }, { ["y"] = -1, ["x"] = -4, ["name"] = "default:dirt", ["z"] = -1, ["meta"] = { ["inventory"] = {  }, ["fields"] = {  } }, ["param2"] = 0, ["param1"] = 0 }, { ["y"] = -1, ["x"] = -4, ["name"] = "default:dirt", ["z"] = 0, ["meta"] = { ["inventory"] = {  }, ["fields"] = {  } }, ["param2"] = 0, ["param1"] = 0 }, { ["y"] = -1, ["x"] = -4, ["name"] = "default:dirt", ["z"] = 1, ["meta"] = { ["inventory"] = {  }, ["fields"] = {  } }, ["param2"] = 0, ["param1"] = 0 }, { ["y"] = -1, ["x"] = -4, ["name"] = "default:dirt", ["z"] = 2, ["meta"] = { ["inventory"] = {  }, ["fields"] = {  } }, ["param2"] = 0, ["param1"] = 0 }, { ["y"] = -1, ["x"] = -4, ["name"] = "default:dirt", ["z"] = 3, ["meta"] = { ["inventory"] = {  }, ["fields"] = {  } }, ["param2"] = 0, ["param1"] = 0 }, { ["y"] = -1, ["x"] = -4, ["name"] = "default:dirt", ["z"] = 4, ["meta"] = { ["inventory"] = {  }, ["fields"] = {  } }, ["param2"] = 0, ["param1"] = 0 }, { ["y"] = -1, ["x"] = -4, ["name"] = "default:dirt", ["z"] = -5, ["meta"] = { ["inventory"] = {  }, ["fields"] = {  } }, ["param2"] = 0, ["param1"] = 0 }, { ["y"] = 0, ["x"] = -4, ["name"] = "default:dirt", ["z"] = -4, ["meta"] = { ["inventory"] = {  }, ["fields"] = {  } }, ["param2"] = 0, ["param1"] = 0 }, { ["y"] = 0, ["x"] = -4, ["name"] = "default:dirt", ["z"] = -3, ["meta"] = { ["inventory"] = {  }, ["fields"] = {  } }, ["param2"] = 0, ["param1"] = 0 }, { ["y"] = 0, ["x"] = -4, ["name"] = "default:dirt", ["z"] = -2, ["meta"] = { ["inventory"] = {  }, ["fields"] = {  } }, ["param2"] = 0, ["param1"] = 0 }, { ["y"] = 0, ["x"] = -4, ["name"] = "default:dirt", ["z"] = -1, ["meta"] = { ["inventory"] = {  }, ["fields"] = {  } }, ["param2"] = 0, ["param1"] = 0 }, { ["y"] = 0, ["x"] = -4, ["name"] = "default:dirt", ["z"] = 0, ["meta"] = { ["inventory"] = {  }, ["fields"] = {  } }, ["param2"] = 0, ["param1"] = 0 }, { ["y"] = 0, ["x"] = -4, ["name"] = "default:dirt", ["z"] = 1, ["meta"] = { ["inventory"] = {  }, ["fields"] = {  } }, ["param2"] = 0, ["param1"] = 0 }, { ["y"] = 0, ["x"] = -4, ["name"] = "default:dirt", ["z"] = 2, ["meta"] = { ["inventory"] = {  }, ["fields"] = {  } }, ["param2"] = 0, ["param1"] = 0 }, { ["y"] = 0, ["x"] = -4, ["name"] = "default:dirt", ["z"] = 3, ["meta"] = { ["inventory"] = {  }, ["fields"] = {  } }, ["param2"] = 0, ["param1"] = 0 }, { ["y"] = 0, ["x"] = -4, ["name"] = "default:dirt", ["z"] = 4, ["meta"] = { ["inventory"] = {  }, ["fields"] = {  } }, ["param2"] = 0, ["param1"] = 0 }, { ["y"] = 0, ["x"] = -4, ["name"] = "default:dirt", ["z"] = -5, ["meta"] = { ["inventory"] = {  }, ["fields"] = {  } }, ["param2"] = 0, ["param1"] = 0 }, { ["y"] = 1, ["x"] = -4, ["name"] = "default:dirt", ["z"] = -4, ["meta"] = { ["inventory"] = {  }, ["fields"] = {  } }, ["param2"] = 0, ["param1"] = 0 }, { ["y"] = 1, ["x"] = -4, ["name"] = "default:dirt", ["z"] = -3, ["meta"] = { ["inventory"] = {  }, ["fields"] = {  } }, ["param2"] = 0, ["param1"] = 0 }, { ["y"] = 1, ["x"] = -4, ["name"] = "default:dirt", ["z"] = -2, ["meta"] = { ["inventory"] = {  }, ["fields"] = {  } }, ["param2"] = 0, ["param1"] = 0 }, { ["y"] = 1, ["x"] = -4, ["name"] = "default:dirt", ["z"] = -1, ["meta"] = { ["inventory"] = {  }, ["fields"] = {  } }, ["param2"] = 0, ["param1"] = 0 }, { ["y"] = 1, ["x"] = -4, ["name"] = "default:dirt", ["z"] = 0, ["meta"] = { ["inventory"] = {  }, ["fields"] = {  } }, ["param2"] = 0, ["param1"] = 0 }, { ["y"] = 1, ["x"] = -4, ["name"] = "default:dirt", ["z"] = 1, ["meta"] = { ["inventory"] = {  }, ["fields"] = {  } }, ["param2"] = 0, ["param1"] = 0 }, { ["y"] = 1, ["x"] = -4, ["name"] = "default:dirt", ["z"] = 2, ["meta"] = { ["inventory"] = {  }, ["fields"] = {  } }, ["param2"] = 0, ["param1"] = 0 }, { ["y"] = 1, ["x"] = -4, ["name"] = "default:dirt", ["z"] = 3, ["meta"] = { ["inventory"] = {  }, ["fields"] = {  } }, ["param2"] = 0, ["param1"] = 0 }, { ["y"] = 1, ["x"] = -4, ["name"] = "default:dirt", ["z"] = 4, ["meta"] = { ["inventory"] = {  }, ["fields"] = {  } }, ["param2"] = 0, ["param1"] = 0 }, { ["y"] = 1, ["x"] = -4, ["name"] = "default:dirt", ["z"] = -5, ["meta"] = { ["inventory"] = {  }, ["fields"] = {  } }, ["param2"] = 0, ["param1"] = 0 }, { ["y"] = 2, ["x"] = -4, ["name"] = "default:dirt", ["z"] = -4, ["meta"] = { ["inventory"] = {  }, ["fields"] = {  } }, ["param2"] = 0, ["param1"] = 0 }, { ["y"] = 2, ["x"] = -4, ["name"] = "default:dirt", ["z"] = -3, ["meta"] = { ["inventory"] = {  }, ["fields"] = {  } }, ["param2"] = 0, ["param1"] = 0 }, { ["y"] = 2, ["x"] = -4, ["name"] = "default:dirt", ["z"] = -2, ["meta"] = { ["inventory"] = {  }, ["fields"] = {  } }, ["param2"] = 0, ["param1"] = 0 }, { ["y"] = 2, ["x"] = -4, ["name"] = "default:dirt", ["z"] = -1, ["meta"] = { ["inventory"] = {  }, ["fields"] = {  } }, ["param2"] = 0, ["param1"] = 0 }, { ["y"] = 2, ["x"] = -4, ["name"] = "default:dirt", ["z"] = 0, ["meta"] = { ["inventory"] = {  }, ["fields"] = {  } }, ["param2"] = 0, ["param1"] = 0 }, { ["y"] = 2, ["x"] = -4, ["name"] = "default:dirt", ["z"] = 1, ["meta"] = { ["inventory"] = {  }, ["fields"] = {  } }, ["param2"] = 0, ["param1"] = 0 }, { ["y"] = 2, ["x"] = -4, ["name"] = "default:dirt", ["z"] = 2, ["meta"] = { ["inventory"] = {  }, ["fields"] = {  } }, ["param2"] = 0, ["param1"] = 0 }, { ["y"] = 2, ["x"] = -4, ["name"] = "default:dirt", ["z"] = 3, ["meta"] = { ["inventory"] = {  }, ["fields"] = {  } }, ["param2"] = 0, ["param1"] = 0 }, { ["y"] = 2, ["x"] = -4, ["name"] = "default:dirt", ["z"] = 4, ["meta"] = { ["inventory"] = {  }, ["fields"] = {  } }, ["param2"] = 0, ["param1"] = 0 }, { ["y"] = 2, ["x"] = -4, ["name"] = "default:dirt", ["z"] = -5, ["meta"] = { ["inventory"] = {  }, ["fields"] = {  } }, ["param2"] = 0, ["param1"] = 0 }, { ["y"] = 3, ["x"] = -4, ["name"] = "default:dirt", ["z"] = -4, ["meta"] = { ["inventory"] = {  }, ["fields"] = {  } }, ["param2"] = 0, ["param1"] = 0 }, { ["y"] = 3, ["x"] = -4, ["name"] = "default:dirt", ["z"] = -3, ["meta"] = { ["inventory"] = {  }, ["fields"] = {  } }, ["param2"] = 0, ["param1"] = 0 }, { ["y"] = 3, ["x"] = -4, ["name"] = "default:dirt", ["z"] = -2, ["meta"] = { ["inventory"] = {  }, ["fields"] = {  } }, ["param2"] = 0, ["param1"] = 0 }, { ["y"] = 3, ["x"] = -4, ["name"] = "default:dirt", ["z"] = -1, ["meta"] = { ["inventory"] = {  }, ["fields"] = {  } }, ["param2"] = 0, ["param1"] = 0 }, { ["y"] = 3, ["x"] = -4, ["name"] = "default:dirt", ["z"] = 0, ["meta"] = { ["inventory"] = {  }, ["fields"] = {  } }, ["param2"] = 0, ["param1"] = 0 }, { ["y"] = 3, ["x"] = -4, ["name"] = "default:dirt", ["z"] = 1, ["meta"] = { ["inventory"] = {  }, ["fields"] = {  } }, ["param2"] = 0, ["param1"] = 0 }, { ["y"] = 3, ["x"] = -4, ["name"] = "default:dirt", ["z"] = 2, ["meta"] = { ["inventory"] = {  }, ["fields"] = {  } }, ["param2"] = 0, ["param1"] = 0 }, { ["y"] = 3, ["x"] = -4, ["name"] = "default:dirt", ["z"] = 3, ["meta"] = { ["inventory"] = {  }, ["fields"] = {  } }, ["param2"] = 0, ["param1"] = 0 }, { ["y"] = 3, ["x"] = -4, ["name"] = "default:dirt", ["z"] = 4, ["meta"] = { ["inventory"] = {  }, ["fields"] = {  } }, ["param2"] = 0, ["param1"] = 0 }, { ["y"] = 3, ["x"] = -4, ["name"] = "default:dirt", ["z"] = -5, ["meta"] = { ["inventory"] = {  }, ["fields"] = {  } }, ["param2"] = 0, ["param1"] = 0 }, { ["y"] = 4, ["x"] = -4, ["name"] = "default:dirt", ["z"] = -4, ["meta"] = { ["inventory"] = {  }, ["fields"] = {  } }, ["param2"] = 0, ["param1"] = 0 }, { ["y"] = 4, ["x"] = -4, ["name"] = "default:dirt", ["z"] = -3, ["meta"] = { ["inventory"] = {  }, ["fields"] = {  } }, ["param2"] = 0, ["param1"] = 0 }, { ["y"] = 4, ["x"] = -4, ["name"] = "default:dirt", ["z"] = -2, ["meta"] = { ["inventory"] = {  }, ["fields"] = {  } }, ["param2"] = 0, ["param1"] = 0 }, { ["y"] = 4, ["x"] = -4, ["name"] = "default:dirt", ["z"] = -1, ["meta"] = { ["inventory"] = {  }, ["fields"] = {  } }, ["param2"] = 0, ["param1"] = 0 }, { ["y"] = 4, ["x"] = -4, ["name"] = "default:dirt", ["z"] = 0, ["meta"] = { ["inventory"] = {  }, ["fields"] = {  } }, ["param2"] = 0, ["param1"] = 0 }, { ["y"] = 4, ["x"] = -4, ["name"] = "default:dirt", ["z"] = 1, ["meta"] = { ["inventory"] = {  }, ["fields"] = {  } }, ["param2"] = 0, ["param1"] = 0 }, { ["y"] = 4, ["x"] = -4, ["name"] = "default:dirt", ["z"] = 2, ["meta"] = { ["inventory"] = {  }, ["fields"] = {  } }, ["param2"] = 0, ["param1"] = 0 }, { ["y"] = 4, ["x"] = -4, ["name"] = "default:dirt", ["z"] = 3, ["meta"] = { ["inventory"] = {  }, ["fields"] = {  } }, ["param2"] = 0, ["param1"] = 0 }, { ["y"] = 4, ["x"] = -4, ["name"] = "default:dirt", ["z"] = 4, ["meta"] = { ["inventory"] = {  }, ["fields"] = {  } }, ["param2"] = 0, ["param1"] = 0 }, { ["y"] = 4, ["x"] = -4, ["name"] = "default:dirt", ["z"] = -5, ["meta"] = { ["inventory"] = {  }, ["fields"] = {  } }, ["param2"] = 0, ["param1"] = 0 }, { ["y"] = -5, ["x"] = -4, ["name"] = "default:dirt", ["z"] = -4, ["meta"] = { ["inventory"] = {  }, ["fields"] = {  } }, ["param2"] = 0, ["param1"] = 0 }, { ["y"] = -5, ["x"] = -4, ["name"] = "default:dirt", ["z"] = -3, ["meta"] = { ["inventory"] = {  }, ["fields"] = {  } }, ["param2"] = 0, ["param1"] = 0 }, { ["y"] = -5, ["x"] = -4, ["name"] = "default:dirt", ["z"] = -2, ["meta"] = { ["inventory"] = {  }, ["fields"] = {  } }, ["param2"] = 0, ["param1"] = 0 }, { ["y"] = -5, ["x"] = -4, ["name"] = "default:dirt", ["z"] = -1, ["meta"] = { ["inventory"] = {  }, ["fields"] = {  } }, ["param2"] = 0, ["param1"] = 0 }, { ["y"] = -5, ["x"] = -4, ["name"] = "default:dirt", ["z"] = 0, ["meta"] = { ["inventory"] = {  }, ["fields"] = {  } }, ["param2"] = 0, ["param1"] = 0 }, { ["y"] = -5, ["x"] = -4, ["name"] = "default:dirt", ["z"] = 1, ["meta"] = { ["inventory"] = {  }, ["fields"] = {  } }, ["param2"] = 0, ["param1"] = 0 }, { ["y"] = -5, ["x"] = -4, ["name"] = "default:dirt", ["z"] = 2, ["meta"] = { ["inventory"] = {  }, ["fields"] = {  } }, ["param2"] = 0, ["param1"] = 0 }, { ["y"] = -5, ["x"] = -4, ["name"] = "default:dirt", ["z"] = 3, ["meta"] = { ["inventory"] = {  }, ["fields"] = {  } }, ["param2"] = 0, ["param1"] = 0 }, { ["y"] = -5, ["x"] = -4, ["name"] = "default:dirt", ["z"] = 4, ["meta"] = { ["inventory"] = {  }, ["fields"] = {  } }, ["param2"] = 0, ["param1"] = 0 }, { ["y"] = -5, ["x"] = -4, ["name"] = "default:dirt", ["z"] = -5, ["meta"] = { ["inventory"] = {  }, ["fields"] = {  } }, ["param2"] = 0, ["param1"] = 0 }, { ["y"] = -5, ["x"] = -3, ["name"] = "default:dirt", ["z"] = -5, ["meta"] = { ["inventory"] = {  }, ["fields"] = {  } }, ["param2"] = 0, ["param1"] = 0 }, { ["y"] = -5, ["x"] = -3, ["name"] = "default:dirt", ["z"] = -4, ["meta"] = { ["inventory"] = {  }, ["fields"] = {  } }, ["param2"] = 0, ["param1"] = 0 }, { ["y"] = -5, ["x"] = -3, ["name"] = "default:dirt", ["z"] = -3, ["meta"] = { ["inventory"] = {  }, ["fields"] = {  } }, ["param2"] = 0, ["param1"] = 0 }, { ["y"] = -5, ["x"] = -3, ["name"] = "default:dirt", ["z"] = -2, ["meta"] = { ["inventory"] = {  }, ["fields"] = {  } }, ["param2"] = 0, ["param1"] = 0 }, { ["y"] = -5, ["x"] = -3, ["name"] = "default:dirt", ["z"] = -1, ["meta"] = { ["inventory"] = {  }, ["fields"] = {  } }, ["param2"] = 0, ["param1"] = 0 }, { ["y"] = -5, ["x"] = -3, ["name"] = "default:dirt", ["z"] = 0, ["meta"] = { ["inventory"] = {  }, ["fields"] = {  } }, ["param2"] = 0, ["param1"] = 0 }, { ["y"] = -5, ["x"] = -3, ["name"] = "default:dirt", ["z"] = 1, ["meta"] = { ["inventory"] = {  }, ["fields"] = {  } }, ["param2"] = 0, ["param1"] = 0 }, { ["y"] = -5, ["x"] = -3, ["name"] = "default:dirt", ["z"] = 2, ["meta"] = { ["inventory"] = {  }, ["fields"] = {  } }, ["param2"] = 0, ["param1"] = 0 }, { ["y"] = -5, ["x"] = -3, ["name"] = "default:dirt", ["z"] = 3, ["meta"] = { ["inventory"] = {  }, ["fields"] = {  } }, ["param2"] = 0, ["param1"] = 0 }, { ["y"] = -5, ["x"] = -3, ["name"] = "default:dirt", ["z"] = 4, ["meta"] = { ["inventory"] = {  }, ["fields"] = {  } }, ["param2"] = 0, ["param1"] = 0 }, { ["y"] = -4, ["x"] = -3, ["name"] = "default:dirt", ["z"] = -5, ["meta"] = { ["inventory"] = {  }, ["fields"] = {  } }, ["param2"] = 0, ["param1"] = 0 }, { ["y"] = -4, ["x"] = -3, ["name"] = "default:dirt", ["z"] = -4, ["meta"] = { ["inventory"] = {  }, ["fields"] = {  } }, ["param2"] = 0, ["param1"] = 0 }, { ["y"] = -4, ["x"] = -3, ["name"] = "default:dirt", ["z"] = -3, ["meta"] = { ["inventory"] = {  }, ["fields"] = {  } }, ["param2"] = 0, ["param1"] = 0 }, { ["y"] = -4, ["x"] = -3, ["name"] = "default:dirt", ["z"] = -2, ["meta"] = { ["inventory"] = {  }, ["fields"] = {  } }, ["param2"] = 0, ["param1"] = 0 }, { ["y"] = -4, ["x"] = -3, ["name"] = "default:dirt", ["z"] = -1, ["meta"] = { ["inventory"] = {  }, ["fields"] = {  } }, ["param2"] = 0, ["param1"] = 0 }, { ["y"] = -4, ["x"] = -3, ["name"] = "default:dirt", ["z"] = 0, ["meta"] = { ["inventory"] = {  }, ["fields"] = {  } }, ["param2"] = 0, ["param1"] = 0 }, { ["y"] = -4, ["x"] = -3, ["name"] = "default:dirt", ["z"] = 1, ["meta"] = { ["inventory"] = {  }, ["fields"] = {  } }, ["param2"] = 0, ["param1"] = 0 }, { ["y"] = -4, ["x"] = -3, ["name"] = "default:dirt", ["z"] = 2, ["meta"] = { ["inventory"] = {  }, ["fields"] = {  } }, ["param2"] = 0, ["param1"] = 0 }, { ["y"] = -4, ["x"] = -3, ["name"] = "default:dirt", ["z"] = 3, ["meta"] = { ["inventory"] = {  }, ["fields"] = {  } }, ["param2"] = 0, ["param1"] = 0 }, { ["y"] = -4, ["x"] = -3, ["name"] = "default:dirt", ["z"] = 4, ["meta"] = { ["inventory"] = {  }, ["fields"] = {  } }, ["param2"] = 0, ["param1"] = 0 }, { ["y"] = -3, ["x"] = -3, ["name"] = "default:dirt", ["z"] = -5, ["meta"] = { ["inventory"] = {  }, ["fields"] = {  } }, ["param2"] = 0, ["param1"] = 0 }, { ["y"] = -3, ["x"] = -3, ["name"] = "default:dirt", ["z"] = -4, ["meta"] = { ["inventory"] = {  }, ["fields"] = {  } }, ["param2"] = 0, ["param1"] = 0 }, { ["y"] = -3, ["x"] = -3, ["name"] = "default:dirt", ["z"] = -3, ["meta"] = { ["inventory"] = {  }, ["fields"] = {  } }, ["param2"] = 0, ["param1"] = 0 }, { ["y"] = -3, ["x"] = -3, ["name"] = "default:dirt", ["z"] = -2, ["meta"] = { ["inventory"] = {  }, ["fields"] = {  } }, ["param2"] = 0, ["param1"] = 0 }, { ["y"] = -3, ["x"] = -3, ["name"] = "default:dirt", ["z"] = -1, ["meta"] = { ["inventory"] = {  }, ["fields"] = {  } }, ["param2"] = 0, ["param1"] = 0 }, { ["y"] = -3, ["x"] = -3, ["name"] = "default:dirt", ["z"] = 0, ["meta"] = { ["inventory"] = {  }, ["fields"] = {  } }, ["param2"] = 0, ["param1"] = 0 }, { ["y"] = -3, ["x"] = -3, ["name"] = "default:dirt", ["z"] = 1, ["meta"] = { ["inventory"] = {  }, ["fields"] = {  } }, ["param2"] = 0, ["param1"] = 0 }, { ["y"] = -3, ["x"] = -3, ["name"] = "default:dirt", ["z"] = 2, ["meta"] = { ["inventory"] = {  }, ["fields"] = {  } }, ["param2"] = 0, ["param1"] = 0 }, { ["y"] = -3, ["x"] = -3, ["name"] = "default:dirt", ["z"] = 3, ["meta"] = { ["inventory"] = {  }, ["fields"] = {  } }, ["param2"] = 0, ["param1"] = 0 }, { ["y"] = -3, ["x"] = -3, ["name"] = "default:dirt", ["z"] = 4, ["meta"] = { ["inventory"] = {  }, ["fields"] = {  } }, ["param2"] = 0, ["param1"] = 0 }, { ["y"] = -2, ["x"] = -3, ["name"] = "default:dirt", ["z"] = -5, ["meta"] = { ["inventory"] = {  }, ["fields"] = {  } }, ["param2"] = 0, ["param1"] = 0 }, { ["y"] = -2, ["x"] = -3, ["name"] = "default:dirt", ["z"] = -4, ["meta"] = { ["inventory"] = {  }, ["fields"] = {  } }, ["param2"] = 0, ["param1"] = 0 }, { ["y"] = -2, ["x"] = -3, ["name"] = "default:dirt", ["z"] = -3, ["meta"] = { ["inventory"] = {  }, ["fields"] = {  } }, ["param2"] = 0, ["param1"] = 0 }, { ["y"] = -2, ["x"] = -3, ["name"] = "default:dirt", ["z"] = -2, ["meta"] = { ["inventory"] = {  }, ["fields"] = {  } }, ["param2"] = 0, ["param1"] = 0 }, { ["y"] = -2, ["x"] = -3, ["name"] = "default:dirt", ["z"] = -1, ["meta"] = { ["inventory"] = {  }, ["fields"] = {  } }, ["param2"] = 0, ["param1"] = 0 }, { ["y"] = -2, ["x"] = -3, ["name"] = "default:dirt", ["z"] = 0, ["meta"] = { ["inventory"] = {  }, ["fields"] = {  } }, ["param2"] = 0, ["param1"] = 0 }, { ["y"] = -2, ["x"] = -3, ["name"] = "default:dirt", ["z"] = 1, ["meta"] = { ["inventory"] = {  }, ["fields"] = {  } }, ["param2"] = 0, ["param1"] = 0 }, { ["y"] = -2, ["x"] = -3, ["name"] = "default:dirt", ["z"] = 2, ["meta"] = { ["inventory"] = {  }, ["fields"] = {  } }, ["param2"] = 0, ["param1"] = 0 }, { ["y"] = -2, ["x"] = -3, ["name"] = "default:dirt", ["z"] = 3, ["meta"] = { ["inventory"] = {  }, ["fields"] = {  } }, ["param2"] = 0, ["param1"] = 0 }, { ["y"] = -2, ["x"] = -3, ["name"] = "default:dirt", ["z"] = 4, ["meta"] = { ["inventory"] = {  }, ["fields"] = {  } }, ["param2"] = 0, ["param1"] = 0 }, { ["y"] = -1, ["x"] = -3, ["name"] = "default:dirt", ["z"] = -5, ["meta"] = { ["inventory"] = {  }, ["fields"] = {  } }, ["param2"] = 0, ["param1"] = 0 }, { ["y"] = -1, ["x"] = -3, ["name"] = "default:dirt", ["z"] = -4, ["meta"] = { ["inventory"] = {  }, ["fields"] = {  } }, ["param2"] = 0, ["param1"] = 0 }, { ["y"] = -1, ["x"] = -3, ["name"] = "default:dirt", ["z"] = -3, ["meta"] = { ["inventory"] = {  }, ["fields"] = {  } }, ["param2"] = 0, ["param1"] = 0 }, { ["y"] = -1, ["x"] = -3, ["name"] = "default:dirt", ["z"] = -2, ["meta"] = { ["inventory"] = {  }, ["fields"] = {  } }, ["param2"] = 0, ["param1"] = 0 }, { ["y"] = -1, ["x"] = -3, ["name"] = "default:dirt", ["z"] = -1, ["meta"] = { ["inventory"] = {  }, ["fields"] = {  } }, ["param2"] = 0, ["param1"] = 0 }, { ["y"] = -1, ["x"] = -3, ["name"] = "default:dirt", ["z"] = 0, ["meta"] = { ["inventory"] = {  }, ["fields"] = {  } }, ["param2"] = 0, ["param1"] = 0 }, { ["y"] = -1, ["x"] = -3, ["name"] = "default:dirt", ["z"] = 1, ["meta"] = { ["inventory"] = {  }, ["fields"] = {  } }, ["param2"] = 0, ["param1"] = 0 }, { ["y"] = -1, ["x"] = -3, ["name"] = "default:dirt", ["z"] = 2, ["meta"] = { ["inventory"] = {  }, ["fields"] = {  } }, ["param2"] = 0, ["param1"] = 0 }, { ["y"] = -1, ["x"] = -3, ["name"] = "default:dirt", ["z"] = 3, ["meta"] = { ["inventory"] = {  }, ["fields"] = {  } }, ["param2"] = 0, ["param1"] = 0 }, { ["y"] = -1, ["x"] = -3, ["name"] = "default:dirt", ["z"] = 4, ["meta"] = { ["inventory"] = {  }, ["fields"] = {  } }, ["param2"] = 0, ["param1"] = 0 }, { ["y"] = 0, ["x"] = -3, ["name"] = "default:dirt", ["z"] = -5, ["meta"] = { ["inventory"] = {  }, ["fields"] = {  } }, ["param2"] = 0, ["param1"] = 0 }, { ["y"] = 0, ["x"] = -3, ["name"] = "default:dirt", ["z"] = -4, ["meta"] = { ["inventory"] = {  }, ["fields"] = {  } }, ["param2"] = 0, ["param1"] = 0 }, { ["y"] = 0, ["x"] = -3, ["name"] = "default:dirt", ["z"] = -3, ["meta"] = { ["inventory"] = {  }, ["fields"] = {  } }, ["param2"] = 0, ["param1"] = 0 }, { ["y"] = 0, ["x"] = -3, ["name"] = "default:dirt", ["z"] = -2, ["meta"] = { ["inventory"] = {  }, ["fields"] = {  } }, ["param2"] = 0, ["param1"] = 0 }, { ["y"] = 0, ["x"] = -3, ["name"] = "default:dirt", ["z"] = -1, ["meta"] = { ["inventory"] = {  }, ["fields"] = {  } }, ["param2"] = 0, ["param1"] = 0 }, { ["y"] = 0, ["x"] = -3, ["name"] = "default:dirt", ["z"] = 0, ["meta"] = { ["inventory"] = {  }, ["fields"] = {  } }, ["param2"] = 0, ["param1"] = 0 }, { ["y"] = 0, ["x"] = -3, ["name"] = "default:dirt", ["z"] = 1, ["meta"] = { ["inventory"] = {  }, ["fields"] = {  } }, ["param2"] = 0, ["param1"] = 0 }, { ["y"] = 0, ["x"] = -3, ["name"] = "default:dirt", ["z"] = 2, ["meta"] = { ["inventory"] = {  }, ["fields"] = {  } }, ["param2"] = 0, ["param1"] = 0 }, { ["y"] = 0, ["x"] = -3, ["name"] = "default:dirt", ["z"] = 3, ["meta"] = { ["inventory"] = {  }, ["fields"] = {  } }, ["param2"] = 0, ["param1"] = 0 }, { ["y"] = 0, ["x"] = -3, ["name"] = "default:dirt", ["z"] = 4, ["meta"] = { ["inventory"] = {  }, ["fields"] = {  } }, ["param2"] = 0, ["param1"] = 0 }, { ["y"] = 1, ["x"] = -3, ["name"] = "default:dirt", ["z"] = -5, ["meta"] = { ["inventory"] = {  }, ["fields"] = {  } }, ["param2"] = 0, ["param1"] = 0 }, { ["y"] = 1, ["x"] = -3, ["name"] = "default:dirt", ["z"] = -4, ["meta"] = { ["inventory"] = {  }, ["fields"] = {  } }, ["param2"] = 0, ["param1"] = 0 }, { ["y"] = 1, ["x"] = -3, ["name"] = "default:dirt", ["z"] = -3, ["meta"] = { ["inventory"] = {  }, ["fields"] = {  } }, ["param2"] = 0, ["param1"] = 0 }, { ["y"] = 1, ["x"] = -3, ["name"] = "default:dirt", ["z"] = -2, ["meta"] = { ["inventory"] = {  }, ["fields"] = {  } }, ["param2"] = 0, ["param1"] = 0 }, { ["y"] = 1, ["x"] = -3, ["name"] = "default:dirt", ["z"] = -1, ["meta"] = { ["inventory"] = {  }, ["fields"] = {  } }, ["param2"] = 0, ["param1"] = 0 }, { ["y"] = 1, ["x"] = -3, ["name"] = "default:dirt", ["z"] = 0, ["meta"] = { ["inventory"] = {  }, ["fields"] = {  } }, ["param2"] = 0, ["param1"] = 0 }, { ["y"] = 1, ["x"] = -3, ["name"] = "default:dirt", ["z"] = 1, ["meta"] = { ["inventory"] = {  }, ["fields"] = {  } }, ["param2"] = 0, ["param1"] = 0 }, { ["y"] = 1, ["x"] = -3, ["name"] = "default:dirt", ["z"] = 2, ["meta"] = { ["inventory"] = {  }, ["fields"] = {  } }, ["param2"] = 0, ["param1"] = 0 }, { ["y"] = 1, ["x"] = -3, ["name"] = "default:dirt", ["z"] = 3, ["meta"] = { ["inventory"] = {  }, ["fields"] = {  } }, ["param2"] = 0, ["param1"] = 0 }, { ["y"] = 1, ["x"] = -3, ["name"] = "default:dirt", ["z"] = 4, ["meta"] = { ["inventory"] = {  }, ["fields"] = {  } }, ["param2"] = 0, ["param1"] = 0 }, { ["y"] = 2, ["x"] = -3, ["name"] = "default:dirt", ["z"] = -5, ["meta"] = { ["inventory"] = {  }, ["fields"] = {  } }, ["param2"] = 0, ["param1"] = 0 }, { ["y"] = 2, ["x"] = -3, ["name"] = "default:dirt", ["z"] = -4, ["meta"] = { ["inventory"] = {  }, ["fields"] = {  } }, ["param2"] = 0, ["param1"] = 0 }, { ["y"] = 2, ["x"] = -3, ["name"] = "default:dirt", ["z"] = -3, ["meta"] = { ["inventory"] = {  }, ["fields"] = {  } }, ["param2"] = 0, ["param1"] = 0 }, { ["y"] = 2, ["x"] = -3, ["name"] = "default:dirt", ["z"] = -2, ["meta"] = { ["inventory"] = {  }, ["fields"] = {  } }, ["param2"] = 0, ["param1"] = 0 }, { ["y"] = 2, ["x"] = -3, ["name"] = "default:dirt", ["z"] = -1, ["meta"] = { ["inventory"] = {  }, ["fields"] = {  } }, ["param2"] = 0, ["param1"] = 0 }, { ["y"] = 2, ["x"] = -3, ["name"] = "default:dirt", ["z"] = 0, ["meta"] = { ["inventory"] = {  }, ["fields"] = {  } }, ["param2"] = 0, ["param1"] = 0 }, { ["y"] = 2, ["x"] = -3, ["name"] = "default:dirt", ["z"] = 1, ["meta"] = { ["inventory"] = {  }, ["fields"] = {  } }, ["param2"] = 0, ["param1"] = 0 }, { ["y"] = 2, ["x"] = -3, ["name"] = "default:dirt", ["z"] = 2, ["meta"] = { ["inventory"] = {  }, ["fields"] = {  } }, ["param2"] = 0, ["param1"] = 0 }, { ["y"] = 2, ["x"] = -3, ["name"] = "default:dirt", ["z"] = 3, ["meta"] = { ["inventory"] = {  }, ["fields"] = {  } }, ["param2"] = 0, ["param1"] = 0 }, { ["y"] = 2, ["x"] = -3, ["name"] = "default:dirt", ["z"] = 4, ["meta"] = { ["inventory"] = {  }, ["fields"] = {  } }, ["param2"] = 0, ["param1"] = 0 }, { ["y"] = 3, ["x"] = -3, ["name"] = "default:dirt", ["z"] = -5, ["meta"] = { ["inventory"] = {  }, ["fields"] = {  } }, ["param2"] = 0, ["param1"] = 0 }, { ["y"] = 3, ["x"] = -3, ["name"] = "default:dirt", ["z"] = -4, ["meta"] = { ["inventory"] = {  }, ["fields"] = {  } }, ["param2"] = 0, ["param1"] = 0 }, { ["y"] = 3, ["x"] = -3, ["name"] = "default:dirt", ["z"] = -3, ["meta"] = { ["inventory"] = {  }, ["fields"] = {  } }, ["param2"] = 0, ["param1"] = 0 }, { ["y"] = 3, ["x"] = -3, ["name"] = "default:dirt", ["z"] = -2, ["meta"] = { ["inventory"] = {  }, ["fields"] = {  } }, ["param2"] = 0, ["param1"] = 0 }, { ["y"] = 3, ["x"] = -3, ["name"] = "default:dirt", ["z"] = -1, ["meta"] = { ["inventory"] = {  }, ["fields"] = {  } }, ["param2"] = 0, ["param1"] = 0 }, { ["y"] = 3, ["x"] = -3, ["name"] = "default:dirt", ["z"] = 0, ["meta"] = { ["inventory"] = {  }, ["fields"] = {  } }, ["param2"] = 0, ["param1"] = 0 }, { ["y"] = 3, ["x"] = -3, ["name"] = "default:dirt", ["z"] = 1, ["meta"] = { ["inventory"] = {  }, ["fields"] = {  } }, ["param2"] = 0, ["param1"] = 0 }, { ["y"] = 3, ["x"] = -3, ["name"] = "default:dirt", ["z"] = 2, ["meta"] = { ["inventory"] = {  }, ["fields"] = {  } }, ["param2"] = 0, ["param1"] = 0 }, { ["y"] = 3, ["x"] = -3, ["name"] = "default:dirt", ["z"] = 3, ["meta"] = { ["inventory"] = {  }, ["fields"] = {  } }, ["param2"] = 0, ["param1"] = 0 }, { ["y"] = 3, ["x"] = -3, ["name"] = "default:dirt", ["z"] = 4, ["meta"] = { ["inventory"] = {  }, ["fields"] = {  } }, ["param2"] = 0, ["param1"] = 0 }, { ["y"] = 4, ["x"] = -3, ["name"] = "default:dirt", ["z"] = -5, ["meta"] = { ["inventory"] = {  }, ["fields"] = {  } }, ["param2"] = 0, ["param1"] = 0 }, { ["y"] = 4, ["x"] = -3, ["name"] = "default:dirt", ["z"] = -4, ["meta"] = { ["inventory"] = {  }, ["fields"] = {  } }, ["param2"] = 0, ["param1"] = 0 }, { ["y"] = 4, ["x"] = -3, ["name"] = "default:dirt", ["z"] = -3, ["meta"] = { ["inventory"] = {  }, ["fields"] = {  } }, ["param2"] = 0, ["param1"] = 0 }, { ["y"] = 4, ["x"] = -3, ["name"] = "default:dirt", ["z"] = -2, ["meta"] = { ["inventory"] = {  }, ["fields"] = {  } }, ["param2"] = 0, ["param1"] = 0 }, { ["y"] = 4, ["x"] = -3, ["name"] = "default:dirt", ["z"] = -1, ["meta"] = { ["inventory"] = {  }, ["fields"] = {  } }, ["param2"] = 0, ["param1"] = 0 }, { ["y"] = 4, ["x"] = -3, ["name"] = "default:dirt", ["z"] = 0, ["meta"] = { ["inventory"] = {  }, ["fields"] = {  } }, ["param2"] = 0, ["param1"] = 0 }, { ["y"] = 4, ["x"] = -3, ["name"] = "default:dirt", ["z"] = 1, ["meta"] = { ["inventory"] = {  }, ["fields"] = {  } }, ["param2"] = 0, ["param1"] = 0 }, { ["y"] = 4, ["x"] = -3, ["name"] = "default:dirt", ["z"] = 2, ["meta"] = { ["inventory"] = {  }, ["fields"] = {  } }, ["param2"] = 0, ["param1"] = 0 }, { ["y"] = 4, ["x"] = -3, ["name"] = "default:dirt", ["z"] = 3, ["meta"] = { ["inventory"] = {  }, ["fields"] = {  } }, ["param2"] = 0, ["param1"] = 0 }, { ["y"] = 4, ["x"] = -3, ["name"] = "default:dirt", ["z"] = 4, ["meta"] = { ["inventory"] = {  }, ["fields"] = {  } }, ["param2"] = 0, ["param1"] = 0 }, { ["y"] = -6, ["x"] = -2, ["name"] = "default:dirt", ["z"] = -6, ["meta"] = { ["inventory"] = {  }, ["fields"] = {  } }, ["param2"] = 0, ["param1"] = 0 }, { ["y"] = -6, ["x"] = -2, ["name"] = "default:dirt", ["z"] = -5, ["meta"] = { ["inventory"] = {  }, ["fields"] = {  } }, ["param2"] = 0, ["param1"] = 0 }, { ["y"] = -6, ["x"] = -2, ["name"] = "default:dirt", ["z"] = -4, ["meta"] = { ["inventory"] = {  }, ["fields"] = {  } }, ["param2"] = 0, ["param1"] = 0 }, { ["y"] = -6, ["x"] = -2, ["name"] = "default:dirt", ["z"] = -3, ["meta"] = { ["inventory"] = {  }, ["fields"] = {  } }, ["param2"] = 0, ["param1"] = 0 }, { ["y"] = -6, ["x"] = -2, ["name"] = "default:dirt", ["z"] = -2, ["meta"] = { ["inventory"] = {  }, ["fields"] = {  } }, ["param2"] = 0, ["param1"] = 0 }, { ["y"] = -6, ["x"] = -2, ["name"] = "default:dirt", ["z"] = -1, ["meta"] = { ["inventory"] = {  }, ["fields"] = {  } }, ["param2"] = 0, ["param1"] = 0 }, { ["y"] = -6, ["x"] = -2, ["name"] = "default:dirt", ["z"] = 0, ["meta"] = { ["inventory"] = {  }, ["fields"] = {  } }, ["param2"] = 0, ["param1"] = 0 }, { ["y"] = -6, ["x"] = -2, ["name"] = "default:dirt", ["z"] = 1, ["meta"] = { ["inventory"] = {  }, ["fields"] = {  } }, ["param2"] = 0, ["param1"] = 0 }, { ["y"] = -6, ["x"] = -2, ["name"] = "default:dirt", ["z"] = 2, ["meta"] = { ["inventory"] = {  }, ["fields"] = {  } }, ["param2"] = 0, ["param1"] = 0 }, { ["y"] = -6, ["x"] = -2, ["name"] = "default:dirt", ["z"] = 3, ["meta"] = { ["inventory"] = {  }, ["fields"] = {  } }, ["param2"] = 0, ["param1"] = 0 }, { ["y"] = -6, ["x"] = -2, ["name"] = "default:dirt", ["z"] = 4, ["meta"] = { ["inventory"] = {  }, ["fields"] = {  } }, ["param2"] = 0, ["param1"] = 0 }, { ["y"] = -6, ["x"] = -2, ["name"] = "default:dirt", ["z"] = 5, ["meta"] = { ["inventory"] = {  }, ["fields"] = {  } }, ["param2"] = 0, ["param1"] = 0 }, { ["y"] = -5, ["x"] = -2, ["name"] = "default:dirt", ["z"] = -6, ["meta"] = { ["inventory"] = {  }, ["fields"] = {  } }, ["param2"] = 0, ["param1"] = 0 }, { ["y"] = -5, ["x"] = -2, ["name"] = "default:dirt", ["z"] = -5, ["meta"] = { ["inventory"] = {  }, ["fields"] = {  } }, ["param2"] = 0, ["param1"] = 0 }, { ["y"] = -5, ["x"] = -2, ["name"] = "default:dirt", ["z"] = -4, ["meta"] = { ["inventory"] = {  }, ["fields"] = {  } }, ["param2"] = 0, ["param1"] = 0 }, { ["y"] = -5, ["x"] = -2, ["name"] = "default:dirt", ["z"] = -3, ["meta"] = { ["inventory"] = {  }, ["fields"] = {  } }, ["param2"] = 0, ["param1"] = 0 }, { ["y"] = -5, ["x"] = -2, ["name"] = "default:dirt", ["z"] = -2, ["meta"] = { ["inventory"] = {  }, ["fields"] = {  } }, ["param2"] = 0, ["param1"] = 0 }, { ["y"] = -5, ["x"] = -2, ["name"] = "default:dirt", ["z"] = -1, ["meta"] = { ["inventory"] = {  }, ["fields"] = {  } }, ["param2"] = 0, ["param1"] = 0 }, { ["y"] = -5, ["x"] = -2, ["name"] = "default:dirt", ["z"] = 0, ["meta"] = { ["inventory"] = {  }, ["fields"] = {  } }, ["param2"] = 0, ["param1"] = 0 }, { ["y"] = -5, ["x"] = -2, ["name"] = "default:dirt", ["z"] = 1, ["meta"] = { ["inventory"] = {  }, ["fields"] = {  } }, ["param2"] = 0, ["param1"] = 0 }, { ["y"] = -5, ["x"] = -2, ["name"] = "default:dirt", ["z"] = 2, ["meta"] = { ["inventory"] = {  }, ["fields"] = {  } }, ["param2"] = 0, ["param1"] = 0 }, { ["y"] = -5, ["x"] = -2, ["name"] = "default:dirt", ["z"] = 3, ["meta"] = { ["inventory"] = {  }, ["fields"] = {  } }, ["param2"] = 0, ["param1"] = 0 }, { ["y"] = -5, ["x"] = -2, ["name"] = "default:dirt", ["z"] = 4, ["meta"] = { ["inventory"] = {  }, ["fields"] = {  } }, ["param2"] = 0, ["param1"] = 0 }, { ["y"] = -5, ["x"] = -2, ["name"] = "default:dirt", ["z"] = 5, ["meta"] = { ["inventory"] = {  }, ["fields"] = {  } }, ["param2"] = 0, ["param1"] = 0 }, { ["y"] = -4, ["x"] = -2, ["name"] = "default:dirt", ["z"] = -6, ["meta"] = { ["inventory"] = {  }, ["fields"] = {  } }, ["param2"] = 0, ["param1"] = 0 }, { ["y"] = -4, ["x"] = -2, ["name"] = "default:dirt", ["z"] = -5, ["meta"] = { ["inventory"] = {  }, ["fields"] = {  } }, ["param2"] = 0, ["param1"] = 0 }, { ["y"] = -4, ["x"] = -2, ["name"] = "default:dirt", ["z"] = -4, ["meta"] = { ["inventory"] = {  }, ["fields"] = {  } }, ["param2"] = 0, ["param1"] = 0 }, { ["y"] = -4, ["x"] = -2, ["name"] = "default:dirt", ["z"] = -3, ["meta"] = { ["inventory"] = {  }, ["fields"] = {  } }, ["param2"] = 0, ["param1"] = 0 }, { ["y"] = -4, ["x"] = -2, ["name"] = "default:dirt", ["z"] = -2, ["meta"] = { ["inventory"] = {  }, ["fields"] = {  } }, ["param2"] = 0, ["param1"] = 0 }, { ["y"] = -4, ["x"] = -2, ["name"] = "default:dirt", ["z"] = -1, ["meta"] = { ["inventory"] = {  }, ["fields"] = {  } }, ["param2"] = 0, ["param1"] = 0 }, { ["y"] = -4, ["x"] = -2, ["name"] = "default:dirt", ["z"] = 0, ["meta"] = { ["inventory"] = {  }, ["fields"] = {  } }, ["param2"] = 0, ["param1"] = 0 }, { ["y"] = -4, ["x"] = -2, ["name"] = "default:dirt", ["z"] = 1, ["meta"] = { ["inventory"] = {  }, ["fields"] = {  } }, ["param2"] = 0, ["param1"] = 0 }, { ["y"] = -4, ["x"] = -2, ["name"] = "default:dirt", ["z"] = 2, ["meta"] = { ["inventory"] = {  }, ["fields"] = {  } }, ["param2"] = 0, ["param1"] = 0 }, { ["y"] = -4, ["x"] = -2, ["name"] = "default:dirt", ["z"] = 3, ["meta"] = { ["inventory"] = {  }, ["fields"] = {  } }, ["param2"] = 0, ["param1"] = 0 }, { ["y"] = -4, ["x"] = -2, ["name"] = "default:dirt", ["z"] = 4, ["meta"] = { ["inventory"] = {  }, ["fields"] = {  } }, ["param2"] = 0, ["param1"] = 0 }, { ["y"] = -4, ["x"] = -2, ["name"] = "default:dirt", ["z"] = 5, ["meta"] = { ["inventory"] = {  }, ["fields"] = {  } }, ["param2"] = 0, ["param1"] = 0 }, { ["y"] = -3, ["x"] = -2, ["name"] = "default:dirt", ["z"] = -6, ["meta"] = { ["inventory"] = {  }, ["fields"] = {  } }, ["param2"] = 0, ["param1"] = 0 }, { ["y"] = -3, ["x"] = -2, ["name"] = "default:dirt", ["z"] = -5, ["meta"] = { ["inventory"] = {  }, ["fields"] = {  } }, ["param2"] = 0, ["param1"] = 0 }, { ["y"] = -3, ["x"] = -2, ["name"] = "default:dirt", ["z"] = -4, ["meta"] = { ["inventory"] = {  }, ["fields"] = {  } }, ["param2"] = 0, ["param1"] = 0 }, { ["y"] = -3, ["x"] = -2, ["name"] = "default:dirt", ["z"] = -3, ["meta"] = { ["inventory"] = {  }, ["fields"] = {  } }, ["param2"] = 0, ["param1"] = 0 }, { ["y"] = -3, ["x"] = -2, ["name"] = "default:dirt", ["z"] = -2, ["meta"] = { ["inventory"] = {  }, ["fields"] = {  } }, ["param2"] = 0, ["param1"] = 0 }, { ["y"] = -3, ["x"] = -2, ["name"] = "default:dirt", ["z"] = -1, ["meta"] = { ["inventory"] = {  }, ["fields"] = {  } }, ["param2"] = 0, ["param1"] = 0 }, { ["y"] = -3, ["x"] = -2, ["name"] = "default:dirt", ["z"] = 0, ["meta"] = { ["inventory"] = {  }, ["fields"] = {  } }, ["param2"] = 0, ["param1"] = 0 }, { ["y"] = -3, ["x"] = -2, ["name"] = "default:dirt", ["z"] = 1, ["meta"] = { ["inventory"] = {  }, ["fields"] = {  } }, ["param2"] = 0, ["param1"] = 0 }, { ["y"] = -3, ["x"] = -2, ["name"] = "default:dirt", ["z"] = 2, ["meta"] = { ["inventory"] = {  }, ["fields"] = {  } }, ["param2"] = 0, ["param1"] = 0 }, { ["y"] = -3, ["x"] = -2, ["name"] = "default:dirt", ["z"] = 3, ["meta"] = { ["inventory"] = {  }, ["fields"] = {  } }, ["param2"] = 0, ["param1"] = 0 }, { ["y"] = -3, ["x"] = -2, ["name"] = "default:dirt", ["z"] = 4, ["meta"] = { ["inventory"] = {  }, ["fields"] = {  } }, ["param2"] = 0, ["param1"] = 0 }, { ["y"] = -3, ["x"] = -2, ["name"] = "default:dirt", ["z"] = 5, ["meta"] = { ["inventory"] = {  }, ["fields"] = {  } }, ["param2"] = 0, ["param1"] = 0 }, { ["y"] = -2, ["x"] = -2, ["name"] = "default:dirt", ["z"] = -6, ["meta"] = { ["inventory"] = {  }, ["fields"] = {  } }, ["param2"] = 0, ["param1"] = 0 }, { ["y"] = -2, ["x"] = -2, ["name"] = "default:dirt", ["z"] = -5, ["meta"] = { ["inventory"] = {  }, ["fields"] = {  } }, ["param2"] = 0, ["param1"] = 0 }, { ["y"] = -2, ["x"] = -2, ["name"] = "default:dirt", ["z"] = -4, ["meta"] = { ["inventory"] = {  }, ["fields"] = {  } }, ["param2"] = 0, ["param1"] = 0 }, { ["y"] = -2, ["x"] = -2, ["name"] = "default:dirt", ["z"] = -3, ["meta"] = { ["inventory"] = {  }, ["fields"] = {  } }, ["param2"] = 0, ["param1"] = 0 }, { ["y"] = -2, ["x"] = -2, ["name"] = "default:dirt", ["z"] = -2, ["meta"] = { ["inventory"] = {  }, ["fields"] = {  } }, ["param2"] = 0, ["param1"] = 0 }, { ["y"] = -2, ["x"] = -2, ["name"] = "default:dirt", ["z"] = -1, ["meta"] = { ["inventory"] = {  }, ["fields"] = {  } }, ["param2"] = 0, ["param1"] = 0 }, { ["y"] = -2, ["x"] = -2, ["name"] = "default:dirt", ["z"] = 0, ["meta"] = { ["inventory"] = {  }, ["fields"] = {  } }, ["param2"] = 0, ["param1"] = 0 }, { ["y"] = -2, ["x"] = -2, ["name"] = "default:dirt", ["z"] = 1, ["meta"] = { ["inventory"] = {  }, ["fields"] = {  } }, ["param2"] = 0, ["param1"] = 0 }, { ["y"] = -2, ["x"] = -2, ["name"] = "default:dirt", ["z"] = 2, ["meta"] = { ["inventory"] = {  }, ["fields"] = {  } }, ["param2"] = 0, ["param1"] = 0 }, { ["y"] = -2, ["x"] = -2, ["name"] = "default:dirt", ["z"] = 3, ["meta"] = { ["inventory"] = {  }, ["fields"] = {  } }, ["param2"] = 0, ["param1"] = 0 }, { ["y"] = -2, ["x"] = -2, ["name"] = "default:dirt", ["z"] = 4, ["meta"] = { ["inventory"] = {  }, ["fields"] = {  } }, ["param2"] = 0, ["param1"] = 0 }, { ["y"] = -2, ["x"] = -2, ["name"] = "default:dirt", ["z"] = 5, ["meta"] = { ["inventory"] = {  }, ["fields"] = {  } }, ["param2"] = 0, ["param1"] = 0 }, { ["y"] = -1, ["x"] = -2, ["name"] = "default:dirt", ["z"] = -6, ["meta"] = { ["inventory"] = {  }, ["fields"] = {  } }, ["param2"] = 0, ["param1"] = 0 }, { ["y"] = -1, ["x"] = -2, ["name"] = "default:dirt", ["z"] = -5, ["meta"] = { ["inventory"] = {  }, ["fields"] = {  } }, ["param2"] = 0, ["param1"] = 0 }, { ["y"] = -1, ["x"] = -2, ["name"] = "default:dirt", ["z"] = -4, ["meta"] = { ["inventory"] = {  }, ["fields"] = {  } }, ["param2"] = 0, ["param1"] = 0 }, { ["y"] = -1, ["x"] = -2, ["name"] = "default:dirt", ["z"] = -3, ["meta"] = { ["inventory"] = {  }, ["fields"] = {  } }, ["param2"] = 0, ["param1"] = 0 }, { ["y"] = -1, ["x"] = -2, ["name"] = "default:dirt", ["z"] = -2, ["meta"] = { ["inventory"] = {  }, ["fields"] = {  } }, ["param2"] = 0, ["param1"] = 0 }, { ["y"] = -1, ["x"] = -2, ["name"] = "default:dirt", ["z"] = -1, ["meta"] = { ["inventory"] = {  }, ["fields"] = {  } }, ["param2"] = 0, ["param1"] = 0 }, { ["y"] = -1, ["x"] = -2, ["name"] = "default:dirt", ["z"] = 0, ["meta"] = { ["inventory"] = {  }, ["fields"] = {  } }, ["param2"] = 0, ["param1"] = 0 }, { ["y"] = -1, ["x"] = -2, ["name"] = "default:dirt", ["z"] = 1, ["meta"] = { ["inventory"] = {  }, ["fields"] = {  } }, ["param2"] = 0, ["param1"] = 0 }, { ["y"] = -1, ["x"] = -2, ["name"] = "default:dirt", ["z"] = 2, ["meta"] = { ["inventory"] = {  }, ["fields"] = {  } }, ["param2"] = 0, ["param1"] = 0 }, { ["y"] = -1, ["x"] = -2, ["name"] = "default:dirt", ["z"] = 3, ["meta"] = { ["inventory"] = {  }, ["fields"] = {  } }, ["param2"] = 0, ["param1"] = 0 }, { ["y"] = -1, ["x"] = -2, ["name"] = "default:dirt", ["z"] = 4, ["meta"] = { ["inventory"] = {  }, ["fields"] = {  } }, ["param2"] = 0, ["param1"] = 0 }, { ["y"] = -1, ["x"] = -2, ["name"] = "default:dirt", ["z"] = 5, ["meta"] = { ["inventory"] = {  }, ["fields"] = {  } }, ["param2"] = 0, ["param1"] = 0 }, { ["y"] = 0, ["x"] = -2, ["name"] = "default:dirt", ["z"] = -6, ["meta"] = { ["inventory"] = {  }, ["fields"] = {  } }, ["param2"] = 0, ["param1"] = 0 }, { ["y"] = 0, ["x"] = -2, ["name"] = "default:dirt", ["z"] = -5, ["meta"] = { ["inventory"] = {  }, ["fields"] = {  } }, ["param2"] = 0, ["param1"] = 0 }, { ["y"] = 0, ["x"] = -2, ["name"] = "default:dirt", ["z"] = -4, ["meta"] = { ["inventory"] = {  }, ["fields"] = {  } }, ["param2"] = 0, ["param1"] = 0 }, { ["y"] = 0, ["x"] = -2, ["name"] = "default:dirt", ["z"] = -3, ["meta"] = { ["inventory"] = {  }, ["fields"] = {  } }, ["param2"] = 0, ["param1"] = 0 }, { ["y"] = 0, ["x"] = -2, ["name"] = "default:dirt", ["z"] = -2, ["meta"] = { ["inventory"] = {  }, ["fields"] = {  } }, ["param2"] = 0, ["param1"] = 0 }, { ["y"] = 0, ["x"] = -2, ["name"] = "default:dirt", ["z"] = -1, ["meta"] = { ["inventory"] = {  }, ["fields"] = {  } }, ["param2"] = 0, ["param1"] = 0 }, { ["y"] = 0, ["x"] = -2, ["name"] = "default:dirt", ["z"] = 0, ["meta"] = { ["inventory"] = {  }, ["fields"] = {  } }, ["param2"] = 0, ["param1"] = 0 }, { ["y"] = 0, ["x"] = -2, ["name"] = "default:dirt", ["z"] = 1, ["meta"] = { ["inventory"] = {  }, ["fields"] = {  } }, ["param2"] = 0, ["param1"] = 0 }, { ["y"] = 0, ["x"] = -2, ["name"] = "default:dirt", ["z"] = 2, ["meta"] = { ["inventory"] = {  }, ["fields"] = {  } }, ["param2"] = 0, ["param1"] = 0 }, { ["y"] = 0, ["x"] = -2, ["name"] = "default:dirt", ["z"] = 3, ["meta"] = { ["inventory"] = {  }, ["fields"] = {  } }, ["param2"] = 0, ["param1"] = 0 }, { ["y"] = 0, ["x"] = -2, ["name"] = "default:dirt", ["z"] = 4, ["meta"] = { ["inventory"] = {  }, ["fields"] = {  } }, ["param2"] = 0, ["param1"] = 0 }, { ["y"] = 0, ["x"] = -2, ["name"] = "default:dirt", ["z"] = 5, ["meta"] = { ["inventory"] = {  }, ["fields"] = {  } }, ["param2"] = 0, ["param1"] = 0 }, { ["y"] = 1, ["x"] = -2, ["name"] = "default:dirt", ["z"] = -6, ["meta"] = { ["inventory"] = {  }, ["fields"] = {  } }, ["param2"] = 0, ["param1"] = 0 }, { ["y"] = 1, ["x"] = -2, ["name"] = "default:dirt", ["z"] = -5, ["meta"] = { ["inventory"] = {  }, ["fields"] = {  } }, ["param2"] = 0, ["param1"] = 0 }, { ["y"] = 1, ["x"] = -2, ["name"] = "default:dirt", ["z"] = -4, ["meta"] = { ["inventory"] = {  }, ["fields"] = {  } }, ["param2"] = 0, ["param1"] = 0 }, { ["y"] = 1, ["x"] = -2, ["name"] = "default:dirt", ["z"] = -3, ["meta"] = { ["inventory"] = {  }, ["fields"] = {  } }, ["param2"] = 0, ["param1"] = 0 }, { ["y"] = 1, ["x"] = -2, ["name"] = "default:dirt", ["z"] = -2, ["meta"] = { ["inventory"] = {  }, ["fields"] = {  } }, ["param2"] = 0, ["param1"] = 0 }, { ["y"] = 1, ["x"] = -2, ["name"] = "default:dirt", ["z"] = -1, ["meta"] = { ["inventory"] = {  }, ["fields"] = {  } }, ["param2"] = 0, ["param1"] = 0 }, { ["y"] = 1, ["x"] = -2, ["name"] = "default:dirt", ["z"] = 0, ["meta"] = { ["inventory"] = {  }, ["fields"] = {  } }, ["param2"] = 0, ["param1"] = 0 }, { ["y"] = 1, ["x"] = -2, ["name"] = "default:dirt", ["z"] = 1, ["meta"] = { ["inventory"] = {  }, ["fields"] = {  } }, ["param2"] = 0, ["param1"] = 0 }, { ["y"] = 1, ["x"] = -2, ["name"] = "default:dirt", ["z"] = 2, ["meta"] = { ["inventory"] = {  }, ["fields"] = {  } }, ["param2"] = 0, ["param1"] = 0 }, { ["y"] = 1, ["x"] = -2, ["name"] = "default:dirt", ["z"] = 3, ["meta"] = { ["inventory"] = {  }, ["fields"] = {  } }, ["param2"] = 0, ["param1"] = 0 }, { ["y"] = 1, ["x"] = -2, ["name"] = "default:dirt", ["z"] = 4, ["meta"] = { ["inventory"] = {  }, ["fields"] = {  } }, ["param2"] = 0, ["param1"] = 0 }, { ["y"] = 1, ["x"] = -2, ["name"] = "default:dirt", ["z"] = 5, ["meta"] = { ["inventory"] = {  }, ["fields"] = {  } }, ["param2"] = 0, ["param1"] = 0 }, { ["y"] = 2, ["x"] = -2, ["name"] = "default:dirt", ["z"] = -6, ["meta"] = { ["inventory"] = {  }, ["fields"] = {  } }, ["param2"] = 0, ["param1"] = 0 }, { ["y"] = 2, ["x"] = -2, ["name"] = "default:dirt", ["z"] = -5, ["meta"] = { ["inventory"] = {  }, ["fields"] = {  } }, ["param2"] = 0, ["param1"] = 0 }, { ["y"] = 2, ["x"] = -2, ["name"] = "default:dirt", ["z"] = -4, ["meta"] = { ["inventory"] = {  }, ["fields"] = {  } }, ["param2"] = 0, ["param1"] = 0 }, { ["y"] = 2, ["x"] = -2, ["name"] = "default:dirt", ["z"] = -3, ["meta"] = { ["inventory"] = {  }, ["fields"] = {  } }, ["param2"] = 0, ["param1"] = 0 }, { ["y"] = 2, ["x"] = -2, ["name"] = "default:dirt", ["z"] = -2, ["meta"] = { ["inventory"] = {  }, ["fields"] = {  } }, ["param2"] = 0, ["param1"] = 0 }, { ["y"] = 2, ["x"] = -2, ["name"] = "default:dirt", ["z"] = -1, ["meta"] = { ["inventory"] = {  }, ["fields"] = {  } }, ["param2"] = 0, ["param1"] = 0 }, { ["y"] = 2, ["x"] = -2, ["name"] = "default:dirt", ["z"] = 0, ["meta"] = { ["inventory"] = {  }, ["fields"] = {  } }, ["param2"] = 0, ["param1"] = 0 }, { ["y"] = 2, ["x"] = -2, ["name"] = "default:dirt", ["z"] = 1, ["meta"] = { ["inventory"] = {  }, ["fields"] = {  } }, ["param2"] = 0, ["param1"] = 0 }, { ["y"] = 2, ["x"] = -2, ["name"] = "default:dirt", ["z"] = 2, ["meta"] = { ["inventory"] = {  }, ["fields"] = {  } }, ["param2"] = 0, ["param1"] = 0 }, { ["y"] = 2, ["x"] = -2, ["name"] = "default:dirt", ["z"] = 3, ["meta"] = { ["inventory"] = {  }, ["fields"] = {  } }, ["param2"] = 0, ["param1"] = 0 }, { ["y"] = 2, ["x"] = -2, ["name"] = "default:dirt", ["z"] = 4, ["meta"] = { ["inventory"] = {  }, ["fields"] = {  } }, ["param2"] = 0, ["param1"] = 0 }, { ["y"] = 2, ["x"] = -2, ["name"] = "default:dirt", ["z"] = 5, ["meta"] = { ["inventory"] = {  }, ["fields"] = {  } }, ["param2"] = 0, ["param1"] = 0 }, { ["y"] = 3, ["x"] = -2, ["name"] = "default:dirt", ["z"] = -6, ["meta"] = { ["inventory"] = {  }, ["fields"] = {  } }, ["param2"] = 0, ["param1"] = 0 }, { ["y"] = 3, ["x"] = -2, ["name"] = "default:dirt", ["z"] = -5, ["meta"] = { ["inventory"] = {  }, ["fields"] = {  } }, ["param2"] = 0, ["param1"] = 0 }, { ["y"] = 3, ["x"] = -2, ["name"] = "default:dirt", ["z"] = -4, ["meta"] = { ["inventory"] = {  }, ["fields"] = {  } }, ["param2"] = 0, ["param1"] = 0 }, { ["y"] = 3, ["x"] = -2, ["name"] = "default:dirt", ["z"] = -3, ["meta"] = { ["inventory"] = {  }, ["fields"] = {  } }, ["param2"] = 0, ["param1"] = 0 }, { ["y"] = 3, ["x"] = -2, ["name"] = "default:dirt", ["z"] = -2, ["meta"] = { ["inventory"] = {  }, ["fields"] = {  } }, ["param2"] = 0, ["param1"] = 0 }, { ["y"] = 3, ["x"] = -2, ["name"] = "default:dirt", ["z"] = -1, ["meta"] = { ["inventory"] = {  }, ["fields"] = {  } }, ["param2"] = 0, ["param1"] = 0 }, { ["y"] = 3, ["x"] = -2, ["name"] = "default:dirt", ["z"] = 0, ["meta"] = { ["inventory"] = {  }, ["fields"] = {  } }, ["param2"] = 0, ["param1"] = 0 }, { ["y"] = 3, ["x"] = -2, ["name"] = "default:dirt", ["z"] = 1, ["meta"] = { ["inventory"] = {  }, ["fields"] = {  } }, ["param2"] = 0, ["param1"] = 0 }, { ["y"] = 3, ["x"] = -2, ["name"] = "default:dirt", ["z"] = 2, ["meta"] = { ["inventory"] = {  }, ["fields"] = {  } }, ["param2"] = 0, ["param1"] = 0 }, { ["y"] = 3, ["x"] = -2, ["name"] = "default:dirt", ["z"] = 3, ["meta"] = { ["inventory"] = {  }, ["fields"] = {  } }, ["param2"] = 0, ["param1"] = 0 }, { ["y"] = 3, ["x"] = -2, ["name"] = "default:dirt", ["z"] = 4, ["meta"] = { ["inventory"] = {  }, ["fields"] = {  } }, ["param2"] = 0, ["param1"] = 0 }, { ["y"] = 3, ["x"] = -2, ["name"] = "default:dirt", ["z"] = 5, ["meta"] = { ["inventory"] = {  }, ["fields"] = {  } }, ["param2"] = 0, ["param1"] = 0 }, { ["y"] = 4, ["x"] = -2, ["name"] = "default:dirt", ["z"] = -6, ["meta"] = { ["inventory"] = {  }, ["fields"] = {  } }, ["param2"] = 0, ["param1"] = 0 }, { ["y"] = 4, ["x"] = -2, ["name"] = "default:dirt", ["z"] = -5, ["meta"] = { ["inventory"] = {  }, ["fields"] = {  } }, ["param2"] = 0, ["param1"] = 0 }, { ["y"] = 4, ["x"] = -2, ["name"] = "default:dirt", ["z"] = -4, ["meta"] = { ["inventory"] = {  }, ["fields"] = {  } }, ["param2"] = 0, ["param1"] = 0 }, { ["y"] = 4, ["x"] = -2, ["name"] = "default:dirt", ["z"] = -3, ["meta"] = { ["inventory"] = {  }, ["fields"] = {  } }, ["param2"] = 0, ["param1"] = 0 }, { ["y"] = 4, ["x"] = -2, ["name"] = "default:dirt", ["z"] = -2, ["meta"] = { ["inventory"] = {  }, ["fields"] = {  } }, ["param2"] = 0, ["param1"] = 0 }, { ["y"] = 4, ["x"] = -2, ["name"] = "default:dirt", ["z"] = -1, ["meta"] = { ["inventory"] = {  }, ["fields"] = {  } }, ["param2"] = 0, ["param1"] = 0 }, { ["y"] = 4, ["x"] = -2, ["name"] = "default:dirt", ["z"] = 0, ["meta"] = { ["inventory"] = {  }, ["fields"] = {  } }, ["param2"] = 0, ["param1"] = 0 }, { ["y"] = 4, ["x"] = -2, ["name"] = "default:dirt", ["z"] = 1, ["meta"] = { ["inventory"] = {  }, ["fields"] = {  } }, ["param2"] = 0, ["param1"] = 0 }, { ["y"] = 4, ["x"] = -2, ["name"] = "default:dirt", ["z"] = 2, ["meta"] = { ["inventory"] = {  }, ["fields"] = {  } }, ["param2"] = 0, ["param1"] = 0 }, { ["y"] = 4, ["x"] = -2, ["name"] = "default:dirt", ["z"] = 3, ["meta"] = { ["inventory"] = {  }, ["fields"] = {  } }, ["param2"] = 0, ["param1"] = 0 }, { ["y"] = 4, ["x"] = -2, ["name"] = "default:dirt", ["z"] = 4, ["meta"] = { ["inventory"] = {  }, ["fields"] = {  } }, ["param2"] = 0, ["param1"] = 0 }, { ["y"] = 4, ["x"] = -2, ["name"] = "default:dirt", ["z"] = 5, ["meta"] = { ["inventory"] = {  }, ["fields"] = {  } }, ["param2"] = 0, ["param1"] = 0 }, { ["y"] = 5, ["x"] = -2, ["name"] = "default:dirt", ["z"] = -6, ["meta"] = { ["inventory"] = {  }, ["fields"] = {  } }, ["param2"] = 0, ["param1"] = 0 }, { ["y"] = 5, ["x"] = -2, ["name"] = "default:dirt", ["z"] = -5, ["meta"] = { ["inventory"] = {  }, ["fields"] = {  } }, ["param2"] = 0, ["param1"] = 0 }, { ["y"] = 5, ["x"] = -2, ["name"] = "default:dirt", ["z"] = -4, ["meta"] = { ["inventory"] = {  }, ["fields"] = {  } }, ["param2"] = 0, ["param1"] = 0 }, { ["y"] = 5, ["x"] = -2, ["name"] = "default:dirt", ["z"] = -3, ["meta"] = { ["inventory"] = {  }, ["fields"] = {  } }, ["param2"] = 0, ["param1"] = 0 }, { ["y"] = 5, ["x"] = -2, ["name"] = "default:dirt", ["z"] = -2, ["meta"] = { ["inventory"] = {  }, ["fields"] = {  } }, ["param2"] = 0, ["param1"] = 0 }, { ["y"] = 5, ["x"] = -2, ["name"] = "default:dirt", ["z"] = -1, ["meta"] = { ["inventory"] = {  }, ["fields"] = {  } }, ["param2"] = 0, ["param1"] = 0 }, { ["y"] = 5, ["x"] = -2, ["name"] = "default:dirt", ["z"] = 0, ["meta"] = { ["inventory"] = {  }, ["fields"] = {  } }, ["param2"] = 0, ["param1"] = 0 }, { ["y"] = 5, ["x"] = -2, ["name"] = "default:dirt", ["z"] = 1, ["meta"] = { ["inventory"] = {  }, ["fields"] = {  } }, ["param2"] = 0, ["param1"] = 0 }, { ["y"] = 5, ["x"] = -2, ["name"] = "default:dirt", ["z"] = 2, ["meta"] = { ["inventory"] = {  }, ["fields"] = {  } }, ["param2"] = 0, ["param1"] = 0 }, { ["y"] = 5, ["x"] = -2, ["name"] = "default:dirt", ["z"] = 3, ["meta"] = { ["inventory"] = {  }, ["fields"] = {  } }, ["param2"] = 0, ["param1"] = 0 }, { ["y"] = 5, ["x"] = -2, ["name"] = "default:dirt", ["z"] = 4, ["meta"] = { ["inventory"] = {  }, ["fields"] = {  } }, ["param2"] = 0, ["param1"] = 0 }, { ["y"] = 5, ["x"] = -2, ["name"] = "default:dirt", ["z"] = 5, ["meta"] = { ["inventory"] = {  }, ["fields"] = {  } }, ["param2"] = 0, ["param1"] = 0 }, { ["y"] = -6, ["x"] = -1, ["name"] = "default:dirt", ["z"] = -6, ["meta"] = { ["inventory"] = {  }, ["fields"] = {  } }, ["param2"] = 0, ["param1"] = 0 }, { ["y"] = -6, ["x"] = -1, ["name"] = "default:dirt", ["z"] = -5, ["meta"] = { ["inventory"] = {  }, ["fields"] = {  } }, ["param2"] = 0, ["param1"] = 0 }, { ["y"] = -6, ["x"] = -1, ["name"] = "default:dirt", ["z"] = -4, ["meta"] = { ["inventory"] = {  }, ["fields"] = {  } }, ["param2"] = 0, ["param1"] = 0 }, { ["y"] = -6, ["x"] = -1, ["name"] = "default:dirt", ["z"] = -3, ["meta"] = { ["inventory"] = {  }, ["fields"] = {  } }, ["param2"] = 0, ["param1"] = 0 }, { ["y"] = -6, ["x"] = -1, ["name"] = "default:dirt", ["z"] = -2, ["meta"] = { ["inventory"] = {  }, ["fields"] = {  } }, ["param2"] = 0, ["param1"] = 0 }, { ["y"] = -6, ["x"] = -1, ["name"] = "default:dirt", ["z"] = -1, ["meta"] = { ["inventory"] = {  }, ["fields"] = {  } }, ["param2"] = 0, ["param1"] = 0 }, { ["y"] = -6, ["x"] = -1, ["name"] = "default:dirt", ["z"] = 0, ["meta"] = { ["inventory"] = {  }, ["fields"] = {  } }, ["param2"] = 0, ["param1"] = 0 }, { ["y"] = -6, ["x"] = -1, ["name"] = "default:dirt", ["z"] = 1, ["meta"] = { ["inventory"] = {  }, ["fields"] = {  } }, ["param2"] = 0, ["param1"] = 0 }, { ["y"] = -6, ["x"] = -1, ["name"] = "default:dirt", ["z"] = 2, ["meta"] = { ["inventory"] = {  }, ["fields"] = {  } }, ["param2"] = 0, ["param1"] = 0 }, { ["y"] = -6, ["x"] = -1, ["name"] = "default:dirt", ["z"] = 3, ["meta"] = { ["inventory"] = {  }, ["fields"] = {  } }, ["param2"] = 0, ["param1"] = 0 }, { ["y"] = -6, ["x"] = -1, ["name"] = "default:dirt", ["z"] = 4, ["meta"] = { ["inventory"] = {  }, ["fields"] = {  } }, ["param2"] = 0, ["param1"] = 0 }, { ["y"] = -6, ["x"] = -1, ["name"] = "default:dirt", ["z"] = 5, ["meta"] = { ["inventory"] = {  }, ["fields"] = {  } }, ["param2"] = 0, ["param1"] = 0 }, { ["y"] = -5, ["x"] = -1, ["name"] = "default:dirt", ["z"] = -6, ["meta"] = { ["inventory"] = {  }, ["fields"] = {  } }, ["param2"] = 0, ["param1"] = 0 }, { ["y"] = -5, ["x"] = -1, ["name"] = "default:dirt", ["z"] = -5, ["meta"] = { ["inventory"] = {  }, ["fields"] = {  } }, ["param2"] = 0, ["param1"] = 0 }, { ["y"] = -5, ["x"] = -1, ["name"] = "default:dirt", ["z"] = -4, ["meta"] = { ["inventory"] = {  }, ["fields"] = {  } }, ["param2"] = 0, ["param1"] = 0 }, { ["y"] = -5, ["x"] = -1, ["name"] = "default:dirt", ["z"] = -3, ["meta"] = { ["inventory"] = {  }, ["fields"] = {  } }, ["param2"] = 0, ["param1"] = 0 }, { ["y"] = -5, ["x"] = -1, ["name"] = "default:dirt", ["z"] = -2, ["meta"] = { ["inventory"] = {  }, ["fields"] = {  } }, ["param2"] = 0, ["param1"] = 0 }, { ["y"] = -5, ["x"] = -1, ["name"] = "default:dirt", ["z"] = -1, ["meta"] = { ["inventory"] = {  }, ["fields"] = {  } }, ["param2"] = 0, ["param1"] = 0 }, { ["y"] = -5, ["x"] = -1, ["name"] = "default:dirt", ["z"] = 0, ["meta"] = { ["inventory"] = {  }, ["fields"] = {  } }, ["param2"] = 0, ["param1"] = 0 }, { ["y"] = -5, ["x"] = -1, ["name"] = "default:dirt", ["z"] = 1, ["meta"] = { ["inventory"] = {  }, ["fields"] = {  } }, ["param2"] = 0, ["param1"] = 0 }, { ["y"] = -5, ["x"] = -1, ["name"] = "default:dirt", ["z"] = 2, ["meta"] = { ["inventory"] = {  }, ["fields"] = {  } }, ["param2"] = 0, ["param1"] = 0 }, { ["y"] = -5, ["x"] = -1, ["name"] = "default:dirt", ["z"] = 3, ["meta"] = { ["inventory"] = {  }, ["fields"] = {  } }, ["param2"] = 0, ["param1"] = 0 }, { ["y"] = -5, ["x"] = -1, ["name"] = "default:dirt", ["z"] = 4, ["meta"] = { ["inventory"] = {  }, ["fields"] = {  } }, ["param2"] = 0, ["param1"] = 0 }, { ["y"] = -5, ["x"] = -1, ["name"] = "default:dirt", ["z"] = 5, ["meta"] = { ["inventory"] = {  }, ["fields"] = {  } }, ["param2"] = 0, ["param1"] = 0 }, { ["y"] = -4, ["x"] = -1, ["name"] = "default:dirt", ["z"] = -6, ["meta"] = { ["inventory"] = {  }, ["fields"] = {  } }, ["param2"] = 0, ["param1"] = 0 }, { ["y"] = -4, ["x"] = -1, ["name"] = "default:dirt", ["z"] = -5, ["meta"] = { ["inventory"] = {  }, ["fields"] = {  } }, ["param2"] = 0, ["param1"] = 0 }, { ["y"] = -4, ["x"] = -1, ["name"] = "default:dirt", ["z"] = -4, ["meta"] = { ["inventory"] = {  }, ["fields"] = {  } }, ["param2"] = 0, ["param1"] = 0 }, { ["y"] = -4, ["x"] = -1, ["name"] = "default:dirt", ["z"] = -3, ["meta"] = { ["inventory"] = {  }, ["fields"] = {  } }, ["param2"] = 0, ["param1"] = 0 }, { ["y"] = -4, ["x"] = -1, ["name"] = "default:dirt", ["z"] = -2, ["meta"] = { ["inventory"] = {  }, ["fields"] = {  } }, ["param2"] = 0, ["param1"] = 0 }, { ["y"] = -4, ["x"] = -1, ["name"] = "default:dirt", ["z"] = -1, ["meta"] = { ["inventory"] = {  }, ["fields"] = {  } }, ["param2"] = 0, ["param1"] = 0 }, { ["y"] = -4, ["x"] = -1, ["name"] = "default:dirt", ["z"] = 0, ["meta"] = { ["inventory"] = {  }, ["fields"] = {  } }, ["param2"] = 0, ["param1"] = 0 }, { ["y"] = -4, ["x"] = -1, ["name"] = "default:dirt", ["z"] = 1, ["meta"] = { ["inventory"] = {  }, ["fields"] = {  } }, ["param2"] = 0, ["param1"] = 0 }, { ["y"] = -4, ["x"] = -1, ["name"] = "default:dirt", ["z"] = 2, ["meta"] = { ["inventory"] = {  }, ["fields"] = {  } }, ["param2"] = 0, ["param1"] = 0 }, { ["y"] = -4, ["x"] = -1, ["name"] = "default:dirt", ["z"] = 3, ["meta"] = { ["inventory"] = {  }, ["fields"] = {  } }, ["param2"] = 0, ["param1"] = 0 }, { ["y"] = -4, ["x"] = -1, ["name"] = "default:dirt", ["z"] = 4, ["meta"] = { ["inventory"] = {  }, ["fields"] = {  } }, ["param2"] = 0, ["param1"] = 0 }, { ["y"] = -4, ["x"] = -1, ["name"] = "default:dirt", ["z"] = 5, ["meta"] = { ["inventory"] = {  }, ["fields"] = {  } }, ["param2"] = 0, ["param1"] = 0 }, { ["y"] = -3, ["x"] = -1, ["name"] = "default:dirt", ["z"] = -6, ["meta"] = { ["inventory"] = {  }, ["fields"] = {  } }, ["param2"] = 0, ["param1"] = 0 }, { ["y"] = -3, ["x"] = -1, ["name"] = "default:dirt", ["z"] = -5, ["meta"] = { ["inventory"] = {  }, ["fields"] = {  } }, ["param2"] = 0, ["param1"] = 0 }, { ["y"] = -3, ["x"] = -1, ["name"] = "default:dirt", ["z"] = -4, ["meta"] = { ["inventory"] = {  }, ["fields"] = {  } }, ["param2"] = 0, ["param1"] = 0 }, { ["y"] = -3, ["x"] = -1, ["name"] = "default:dirt", ["z"] = -3, ["meta"] = { ["inventory"] = {  }, ["fields"] = {  } }, ["param2"] = 0, ["param1"] = 0 }, { ["y"] = -3, ["x"] = -1, ["name"] = "default:dirt", ["z"] = -2, ["meta"] = { ["inventory"] = {  }, ["fields"] = {  } }, ["param2"] = 0, ["param1"] = 0 }, { ["y"] = -3, ["x"] = -1, ["name"] = "default:dirt", ["z"] = -1, ["meta"] = { ["inventory"] = {  }, ["fields"] = {  } }, ["param2"] = 0, ["param1"] = 0 }, { ["y"] = -3, ["x"] = -1, ["name"] = "default:dirt", ["z"] = 0, ["meta"] = { ["inventory"] = {  }, ["fields"] = {  } }, ["param2"] = 0, ["param1"] = 0 }, { ["y"] = -3, ["x"] = -1, ["name"] = "default:dirt", ["z"] = 1, ["meta"] = { ["inventory"] = {  }, ["fields"] = {  } }, ["param2"] = 0, ["param1"] = 0 }, { ["y"] = -3, ["x"] = -1, ["name"] = "default:dirt", ["z"] = 2, ["meta"] = { ["inventory"] = {  }, ["fields"] = {  } }, ["param2"] = 0, ["param1"] = 0 }, { ["y"] = -3, ["x"] = -1, ["name"] = "default:dirt", ["z"] = 3, ["meta"] = { ["inventory"] = {  }, ["fields"] = {  } }, ["param2"] = 0, ["param1"] = 0 }, { ["y"] = -3, ["x"] = -1, ["name"] = "default:dirt", ["z"] = 4, ["meta"] = { ["inventory"] = {  }, ["fields"] = {  } }, ["param2"] = 0, ["param1"] = 0 }, { ["y"] = -3, ["x"] = -1, ["name"] = "default:dirt", ["z"] = 5, ["meta"] = { ["inventory"] = {  }, ["fields"] = {  } }, ["param2"] = 0, ["param1"] = 0 }, { ["y"] = -2, ["x"] = -1, ["name"] = "default:dirt", ["z"] = -6, ["meta"] = { ["inventory"] = {  }, ["fields"] = {  } }, ["param2"] = 0, ["param1"] = 0 }, { ["y"] = -2, ["x"] = -1, ["name"] = "default:dirt", ["z"] = -5, ["meta"] = { ["inventory"] = {  }, ["fields"] = {  } }, ["param2"] = 0, ["param1"] = 0 }, { ["y"] = -2, ["x"] = -1, ["name"] = "default:dirt", ["z"] = -4, ["meta"] = { ["inventory"] = {  }, ["fields"] = {  } }, ["param2"] = 0, ["param1"] = 0 }, { ["y"] = -2, ["x"] = -1, ["name"] = "default:dirt", ["z"] = -3, ["meta"] = { ["inventory"] = {  }, ["fields"] = {  } }, ["param2"] = 0, ["param1"] = 0 }, { ["y"] = -2, ["x"] = -1, ["name"] = "default:dirt", ["z"] = -2, ["meta"] = { ["inventory"] = {  }, ["fields"] = {  } }, ["param2"] = 0, ["param1"] = 0 }, { ["y"] = -2, ["x"] = -1, ["name"] = "default:dirt", ["z"] = -1, ["meta"] = { ["inventory"] = {  }, ["fields"] = {  } }, ["param2"] = 0, ["param1"] = 0 }, { ["y"] = -2, ["x"] = -1, ["name"] = "default:dirt", ["z"] = 0, ["meta"] = { ["inventory"] = {  }, ["fields"] = {  } }, ["param2"] = 0, ["param1"] = 0 }, { ["y"] = -2, ["x"] = -1, ["name"] = "default:dirt", ["z"] = 1, ["meta"] = { ["inventory"] = {  }, ["fields"] = {  } }, ["param2"] = 0, ["param1"] = 0 }, { ["y"] = -2, ["x"] = -1, ["name"] = "default:dirt", ["z"] = 2, ["meta"] = { ["inventory"] = {  }, ["fields"] = {  } }, ["param2"] = 0, ["param1"] = 0 }, { ["y"] = -2, ["x"] = -1, ["name"] = "default:dirt", ["z"] = 3, ["meta"] = { ["inventory"] = {  }, ["fields"] = {  } }, ["param2"] = 0, ["param1"] = 0 }, { ["y"] = -2, ["x"] = -1, ["name"] = "default:dirt", ["z"] = 4, ["meta"] = { ["inventory"] = {  }, ["fields"] = {  } }, ["param2"] = 0, ["param1"] = 0 }, { ["y"] = -2, ["x"] = -1, ["name"] = "default:dirt", ["z"] = 5, ["meta"] = { ["inventory"] = {  }, ["fields"] = {  } }, ["param2"] = 0, ["param1"] = 0 }, { ["y"] = -1, ["x"] = -1, ["name"] = "default:dirt", ["z"] = -6, ["meta"] = { ["inventory"] = {  }, ["fields"] = {  } }, ["param2"] = 0, ["param1"] = 0 }, { ["y"] = -1, ["x"] = -1, ["name"] = "default:dirt", ["z"] = -5, ["meta"] = { ["inventory"] = {  }, ["fields"] = {  } }, ["param2"] = 0, ["param1"] = 0 }, { ["y"] = -1, ["x"] = -1, ["name"] = "default:dirt", ["z"] = -4, ["meta"] = { ["inventory"] = {  }, ["fields"] = {  } }, ["param2"] = 0, ["param1"] = 0 }, { ["y"] = -1, ["x"] = -1, ["name"] = "default:dirt", ["z"] = -3, ["meta"] = { ["inventory"] = {  }, ["fields"] = {  } }, ["param2"] = 0, ["param1"] = 0 }, { ["y"] = -1, ["x"] = -1, ["name"] = "default:dirt", ["z"] = -2, ["meta"] = { ["inventory"] = {  }, ["fields"] = {  } }, ["param2"] = 0, ["param1"] = 0 }, { ["y"] = -1, ["x"] = -1, ["name"] = "default:dirt", ["z"] = -1, ["meta"] = { ["inventory"] = {  }, ["fields"] = {  } }, ["param2"] = 0, ["param1"] = 0 }, { ["y"] = -1, ["x"] = -1, ["name"] = "default:dirt", ["z"] = 0, ["meta"] = { ["inventory"] = {  }, ["fields"] = {  } }, ["param2"] = 0, ["param1"] = 0 }, { ["y"] = -1, ["x"] = -1, ["name"] = "default:dirt", ["z"] = 1, ["meta"] = { ["inventory"] = {  }, ["fields"] = {  } }, ["param2"] = 0, ["param1"] = 0 }, { ["y"] = -1, ["x"] = -1, ["name"] = "default:dirt", ["z"] = 2, ["meta"] = { ["inventory"] = {  }, ["fields"] = {  } }, ["param2"] = 0, ["param1"] = 0 }, { ["y"] = -1, ["x"] = -1, ["name"] = "default:dirt", ["z"] = 3, ["meta"] = { ["inventory"] = {  }, ["fields"] = {  } }, ["param2"] = 0, ["param1"] = 0 }, { ["y"] = -1, ["x"] = -1, ["name"] = "default:dirt", ["z"] = 4, ["meta"] = { ["inventory"] = {  }, ["fields"] = {  } }, ["param2"] = 0, ["param1"] = 0 }, { ["y"] = -1, ["x"] = -1, ["name"] = "default:dirt", ["z"] = 5, ["meta"] = { ["inventory"] = {  }, ["fields"] = {  } }, ["param2"] = 0, ["param1"] = 0 }, { ["y"] = 0, ["x"] = -1, ["name"] = "default:dirt", ["z"] = -6, ["meta"] = { ["inventory"] = {  }, ["fields"] = {  } }, ["param2"] = 0, ["param1"] = 0 }, { ["y"] = 0, ["x"] = -1, ["name"] = "default:dirt", ["z"] = -5, ["meta"] = { ["inventory"] = {  }, ["fields"] = {  } }, ["param2"] = 0, ["param1"] = 0 }, { ["y"] = 0, ["x"] = -1, ["name"] = "default:dirt", ["z"] = -4, ["meta"] = { ["inventory"] = {  }, ["fields"] = {  } }, ["param2"] = 0, ["param1"] = 0 }, { ["y"] = 0, ["x"] = -1, ["name"] = "default:dirt", ["z"] = -3, ["meta"] = { ["inventory"] = {  }, ["fields"] = {  } }, ["param2"] = 0, ["param1"] = 0 }, { ["y"] = 0, ["x"] = -1, ["name"] = "default:dirt", ["z"] = -2, ["meta"] = { ["inventory"] = {  }, ["fields"] = {  } }, ["param2"] = 0, ["param1"] = 0 }, { ["y"] = 0, ["x"] = -1, ["name"] = "default:dirt", ["z"] = -1, ["meta"] = { ["inventory"] = {  }, ["fields"] = {  } }, ["param2"] = 0, ["param1"] = 0 }, { ["y"] = 0, ["x"] = -1, ["name"] = "default:dirt", ["z"] = 0, ["meta"] = { ["inventory"] = {  }, ["fields"] = {  } }, ["param2"] = 0, ["param1"] = 0 }, { ["y"] = 0, ["x"] = -1, ["name"] = "default:dirt", ["z"] = 1, ["meta"] = { ["inventory"] = {  }, ["fields"] = {  } }, ["param2"] = 0, ["param1"] = 0 }, { ["y"] = 0, ["x"] = -1, ["name"] = "default:dirt", ["z"] = 2, ["meta"] = { ["inventory"] = {  }, ["fields"] = {  } }, ["param2"] = 0, ["param1"] = 0 }, { ["y"] = 0, ["x"] = -1, ["name"] = "default:dirt", ["z"] = 3, ["meta"] = { ["inventory"] = {  }, ["fields"] = {  } }, ["param2"] = 0, ["param1"] = 0 }, { ["y"] = 0, ["x"] = -1, ["name"] = "default:dirt", ["z"] = 4, ["meta"] = { ["inventory"] = {  }, ["fields"] = {  } }, ["param2"] = 0, ["param1"] = 0 }, { ["y"] = 0, ["x"] = -1, ["name"] = "default:dirt", ["z"] = 5, ["meta"] = { ["inventory"] = {  }, ["fields"] = {  } }, ["param2"] = 0, ["param1"] = 0 }, { ["y"] = 1, ["x"] = -1, ["name"] = "default:dirt", ["z"] = -6, ["meta"] = { ["inventory"] = {  }, ["fields"] = {  } }, ["param2"] = 0, ["param1"] = 0 }, { ["y"] = 1, ["x"] = -1, ["name"] = "default:dirt", ["z"] = -5, ["meta"] = { ["inventory"] = {  }, ["fields"] = {  } }, ["param2"] = 0, ["param1"] = 0 }, { ["y"] = 1, ["x"] = -1, ["name"] = "default:dirt", ["z"] = -4, ["meta"] = { ["inventory"] = {  }, ["fields"] = {  } }, ["param2"] = 0, ["param1"] = 0 }, { ["y"] = 1, ["x"] = -1, ["name"] = "default:dirt", ["z"] = -3, ["meta"] = { ["inventory"] = {  }, ["fields"] = {  } }, ["param2"] = 0, ["param1"] = 0 }, { ["y"] = 1, ["x"] = -1, ["name"] = "default:dirt", ["z"] = -2, ["meta"] = { ["inventory"] = {  }, ["fields"] = {  } }, ["param2"] = 0, ["param1"] = 0 }, { ["y"] = 1, ["x"] = -1, ["name"] = "default:dirt", ["z"] = -1, ["meta"] = { ["inventory"] = {  }, ["fields"] = {  } }, ["param2"] = 0, ["param1"] = 0 }, { ["y"] = 1, ["x"] = -1, ["name"] = "default:dirt", ["z"] = 0, ["meta"] = { ["inventory"] = {  }, ["fields"] = {  } }, ["param2"] = 0, ["param1"] = 0 }, { ["y"] = 1, ["x"] = -1, ["name"] = "default:dirt", ["z"] = 1, ["meta"] = { ["inventory"] = {  }, ["fields"] = {  } }, ["param2"] = 0, ["param1"] = 0 }, { ["y"] = 1, ["x"] = -1, ["name"] = "default:dirt", ["z"] = 2, ["meta"] = { ["inventory"] = {  }, ["fields"] = {  } }, ["param2"] = 0, ["param1"] = 0 }, { ["y"] = 1, ["x"] = -1, ["name"] = "default:dirt", ["z"] = 3, ["meta"] = { ["inventory"] = {  }, ["fields"] = {  } }, ["param2"] = 0, ["param1"] = 0 }, { ["y"] = 1, ["x"] = -1, ["name"] = "default:dirt", ["z"] = 4, ["meta"] = { ["inventory"] = {  }, ["fields"] = {  } }, ["param2"] = 0, ["param1"] = 0 }, { ["y"] = 1, ["x"] = -1, ["name"] = "default:dirt", ["z"] = 5, ["meta"] = { ["inventory"] = {  }, ["fields"] = {  } }, ["param2"] = 0, ["param1"] = 0 }, { ["y"] = 2, ["x"] = -1, ["name"] = "default:dirt", ["z"] = -6, ["meta"] = { ["inventory"] = {  }, ["fields"] = {  } }, ["param2"] = 0, ["param1"] = 0 }, { ["y"] = 2, ["x"] = -1, ["name"] = "default:dirt", ["z"] = -5, ["meta"] = { ["inventory"] = {  }, ["fields"] = {  } }, ["param2"] = 0, ["param1"] = 0 }, { ["y"] = 2, ["x"] = -1, ["name"] = "default:dirt", ["z"] = -4, ["meta"] = { ["inventory"] = {  }, ["fields"] = {  } }, ["param2"] = 0, ["param1"] = 0 }, { ["y"] = 2, ["x"] = -1, ["name"] = "default:dirt", ["z"] = -3, ["meta"] = { ["inventory"] = {  }, ["fields"] = {  } }, ["param2"] = 0, ["param1"] = 0 }, { ["y"] = 2, ["x"] = -1, ["name"] = "default:dirt", ["z"] = -2, ["meta"] = { ["inventory"] = {  }, ["fields"] = {  } }, ["param2"] = 0, ["param1"] = 0 }, { ["y"] = 2, ["x"] = -1, ["name"] = "default:dirt", ["z"] = -1, ["meta"] = { ["inventory"] = {  }, ["fields"] = {  } }, ["param2"] = 0, ["param1"] = 0 }, { ["y"] = 2, ["x"] = -1, ["name"] = "default:dirt", ["z"] = 0, ["meta"] = { ["inventory"] = {  }, ["fields"] = {  } }, ["param2"] = 0, ["param1"] = 0 }, { ["y"] = 2, ["x"] = -1, ["name"] = "default:dirt", ["z"] = 1, ["meta"] = { ["inventory"] = {  }, ["fields"] = {  } }, ["param2"] = 0, ["param1"] = 0 }, { ["y"] = 2, ["x"] = -1, ["name"] = "default:dirt", ["z"] = 2, ["meta"] = { ["inventory"] = {  }, ["fields"] = {  } }, ["param2"] = 0, ["param1"] = 0 }, { ["y"] = 2, ["x"] = -1, ["name"] = "default:dirt", ["z"] = 3, ["meta"] = { ["inventory"] = {  }, ["fields"] = {  } }, ["param2"] = 0, ["param1"] = 0 }, { ["y"] = 2, ["x"] = -1, ["name"] = "default:dirt", ["z"] = 4, ["meta"] = { ["inventory"] = {  }, ["fields"] = {  } }, ["param2"] = 0, ["param1"] = 0 }, { ["y"] = 2, ["x"] = -1, ["name"] = "default:dirt", ["z"] = 5, ["meta"] = { ["inventory"] = {  }, ["fields"] = {  } }, ["param2"] = 0, ["param1"] = 0 }, { ["y"] = 3, ["x"] = -1, ["name"] = "default:dirt", ["z"] = -6, ["meta"] = { ["inventory"] = {  }, ["fields"] = {  } }, ["param2"] = 0, ["param1"] = 0 }, { ["y"] = 3, ["x"] = -1, ["name"] = "default:dirt", ["z"] = -5, ["meta"] = { ["inventory"] = {  }, ["fields"] = {  } }, ["param2"] = 0, ["param1"] = 0 }, { ["y"] = 3, ["x"] = -1, ["name"] = "default:dirt", ["z"] = -4, ["meta"] = { ["inventory"] = {  }, ["fields"] = {  } }, ["param2"] = 0, ["param1"] = 0 }, { ["y"] = 3, ["x"] = -1, ["name"] = "default:dirt", ["z"] = -3, ["meta"] = { ["inventory"] = {  }, ["fields"] = {  } }, ["param2"] = 0, ["param1"] = 0 }, { ["y"] = 3, ["x"] = -1, ["name"] = "default:dirt", ["z"] = -2, ["meta"] = { ["inventory"] = {  }, ["fields"] = {  } }, ["param2"] = 0, ["param1"] = 0 }, { ["y"] = 3, ["x"] = -1, ["name"] = "default:dirt", ["z"] = -1, ["meta"] = { ["inventory"] = {  }, ["fields"] = {  } }, ["param2"] = 0, ["param1"] = 0 }, { ["y"] = 3, ["x"] = -1, ["name"] = "default:dirt", ["z"] = 0, ["meta"] = { ["inventory"] = {  }, ["fields"] = {  } }, ["param2"] = 0, ["param1"] = 0 }, { ["y"] = 3, ["x"] = -1, ["name"] = "default:dirt", ["z"] = 1, ["meta"] = { ["inventory"] = {  }, ["fields"] = {  } }, ["param2"] = 0, ["param1"] = 0 }, { ["y"] = 3, ["x"] = -1, ["name"] = "default:dirt", ["z"] = 2, ["meta"] = { ["inventory"] = {  }, ["fields"] = {  } }, ["param2"] = 0, ["param1"] = 0 }, { ["y"] = 3, ["x"] = -1, ["name"] = "default:dirt", ["z"] = 3, ["meta"] = { ["inventory"] = {  }, ["fields"] = {  } }, ["param2"] = 0, ["param1"] = 0 }, { ["y"] = 3, ["x"] = -1, ["name"] = "default:dirt", ["z"] = 4, ["meta"] = { ["inventory"] = {  }, ["fields"] = {  } }, ["param2"] = 0, ["param1"] = 0 }, { ["y"] = 3, ["x"] = -1, ["name"] = "default:dirt", ["z"] = 5, ["meta"] = { ["inventory"] = {  }, ["fields"] = {  } }, ["param2"] = 0, ["param1"] = 0 }, { ["y"] = 4, ["x"] = -1, ["name"] = "default:dirt", ["z"] = -6, ["meta"] = { ["inventory"] = {  }, ["fields"] = {  } }, ["param2"] = 0, ["param1"] = 0 }, { ["y"] = 4, ["x"] = -1, ["name"] = "default:dirt", ["z"] = -5, ["meta"] = { ["inventory"] = {  }, ["fields"] = {  } }, ["param2"] = 0, ["param1"] = 0 }, { ["y"] = 4, ["x"] = -1, ["name"] = "default:dirt", ["z"] = -4, ["meta"] = { ["inventory"] = {  }, ["fields"] = {  } }, ["param2"] = 0, ["param1"] = 0 }, { ["y"] = 4, ["x"] = -1, ["name"] = "default:dirt", ["z"] = -3, ["meta"] = { ["inventory"] = {  }, ["fields"] = {  } }, ["param2"] = 0, ["param1"] = 0 }, { ["y"] = 4, ["x"] = -1, ["name"] = "default:dirt", ["z"] = -2, ["meta"] = { ["inventory"] = {  }, ["fields"] = {  } }, ["param2"] = 0, ["param1"] = 0 }, { ["y"] = 4, ["x"] = -1, ["name"] = "default:dirt", ["z"] = -1, ["meta"] = { ["inventory"] = {  }, ["fields"] = {  } }, ["param2"] = 0, ["param1"] = 0 }, { ["y"] = 4, ["x"] = -1, ["name"] = "default:dirt", ["z"] = 0, ["meta"] = { ["inventory"] = {  }, ["fields"] = {  } }, ["param2"] = 0, ["param1"] = 0 }, { ["y"] = 4, ["x"] = -1, ["name"] = "default:dirt", ["z"] = 1, ["meta"] = { ["inventory"] = {  }, ["fields"] = {  } }, ["param2"] = 0, ["param1"] = 0 }, { ["y"] = 4, ["x"] = -1, ["name"] = "default:dirt", ["z"] = 2, ["meta"] = { ["inventory"] = {  }, ["fields"] = {  } }, ["param2"] = 0, ["param1"] = 0 }, { ["y"] = 4, ["x"] = -1, ["name"] = "default:dirt", ["z"] = 3, ["meta"] = { ["inventory"] = {  }, ["fields"] = {  } }, ["param2"] = 0, ["param1"] = 0 }, { ["y"] = 4, ["x"] = -1, ["name"] = "default:dirt", ["z"] = 4, ["meta"] = { ["inventory"] = {  }, ["fields"] = {  } }, ["param2"] = 0, ["param1"] = 0 }, { ["y"] = 4, ["x"] = -1, ["name"] = "default:dirt", ["z"] = 5, ["meta"] = { ["inventory"] = {  }, ["fields"] = {  } }, ["param2"] = 0, ["param1"] = 0 }, { ["y"] = 5, ["x"] = -1, ["name"] = "default:dirt", ["z"] = -6, ["meta"] = { ["inventory"] = {  }, ["fields"] = {  } }, ["param2"] = 0, ["param1"] = 0 }, { ["y"] = 5, ["x"] = -1, ["name"] = "default:dirt", ["z"] = -5, ["meta"] = { ["inventory"] = {  }, ["fields"] = {  } }, ["param2"] = 0, ["param1"] = 0 }, { ["y"] = 5, ["x"] = -1, ["name"] = "default:dirt", ["z"] = -4, ["meta"] = { ["inventory"] = {  }, ["fields"] = {  } }, ["param2"] = 0, ["param1"] = 0 }, { ["y"] = 5, ["x"] = -1, ["name"] = "default:dirt", ["z"] = -3, ["meta"] = { ["inventory"] = {  }, ["fields"] = {  } }, ["param2"] = 0, ["param1"] = 0 }, { ["y"] = 5, ["x"] = -1, ["name"] = "default:dirt", ["z"] = -2, ["meta"] = { ["inventory"] = {  }, ["fields"] = {  } }, ["param2"] = 0, ["param1"] = 0 }, { ["y"] = 5, ["x"] = -1, ["name"] = "default:dirt", ["z"] = -1, ["meta"] = { ["inventory"] = {  }, ["fields"] = {  } }, ["param2"] = 0, ["param1"] = 0 }, { ["y"] = 5, ["x"] = -1, ["name"] = "default:dirt", ["z"] = 0, ["meta"] = { ["inventory"] = {  }, ["fields"] = {  } }, ["param2"] = 0, ["param1"] = 0 }, { ["y"] = 5, ["x"] = -1, ["name"] = "default:dirt", ["z"] = 1, ["meta"] = { ["inventory"] = {  }, ["fields"] = {  } }, ["param2"] = 0, ["param1"] = 0 }, { ["y"] = 5, ["x"] = -1, ["name"] = "default:dirt", ["z"] = 2, ["meta"] = { ["inventory"] = {  }, ["fields"] = {  } }, ["param2"] = 0, ["param1"] = 0 }, { ["y"] = 5, ["x"] = -1, ["name"] = "default:dirt", ["z"] = 3, ["meta"] = { ["inventory"] = {  }, ["fields"] = {  } }, ["param2"] = 0, ["param1"] = 0 }, { ["y"] = 5, ["x"] = -1, ["name"] = "default:dirt", ["z"] = 4, ["meta"] = { ["inventory"] = {  }, ["fields"] = {  } }, ["param2"] = 0, ["param1"] = 0 }, { ["y"] = 5, ["x"] = -1, ["name"] = "default:dirt", ["z"] = 5, ["meta"] = { ["inventory"] = {  }, ["fields"] = {  } }, ["param2"] = 0, ["param1"] = 0 }, { ["y"] = -6, ["x"] = 0, ["name"] = "default:dirt", ["z"] = -6, ["meta"] = { ["inventory"] = {  }, ["fields"] = {  } }, ["param2"] = 0, ["param1"] = 0 }, { ["y"] = -6, ["x"] = 0, ["name"] = "default:dirt", ["z"] = -5, ["meta"] = { ["inventory"] = {  }, ["fields"] = {  } }, ["param2"] = 0, ["param1"] = 0 }, { ["y"] = -6, ["x"] = 0, ["name"] = "default:dirt", ["z"] = -4, ["meta"] = { ["inventory"] = {  }, ["fields"] = {  } }, ["param2"] = 0, ["param1"] = 0 }, { ["y"] = -6, ["x"] = 0, ["name"] = "default:dirt", ["z"] = -3, ["meta"] = { ["inventory"] = {  }, ["fields"] = {  } }, ["param2"] = 0, ["param1"] = 0 }, { ["y"] = -6, ["x"] = 0, ["name"] = "default:dirt", ["z"] = -2, ["meta"] = { ["inventory"] = {  }, ["fields"] = {  } }, ["param2"] = 0, ["param1"] = 0 }, { ["y"] = -6, ["x"] = 0, ["name"] = "default:dirt", ["z"] = -1, ["meta"] = { ["inventory"] = {  }, ["fields"] = {  } }, ["param2"] = 0, ["param1"] = 0 }, { ["y"] = -6, ["x"] = 0, ["name"] = "default:dirt", ["z"] = 0, ["meta"] = { ["inventory"] = {  }, ["fields"] = {  } }, ["param2"] = 0, ["param1"] = 0 }, { ["y"] = -6, ["x"] = 0, ["name"] = "default:dirt", ["z"] = 1, ["meta"] = { ["inventory"] = {  }, ["fields"] = {  } }, ["param2"] = 0, ["param1"] = 0 }, { ["y"] = -6, ["x"] = 0, ["name"] = "default:dirt", ["z"] = 2, ["meta"] = { ["inventory"] = {  }, ["fields"] = {  } }, ["param2"] = 0, ["param1"] = 0 }, { ["y"] = -6, ["x"] = 0, ["name"] = "default:dirt", ["z"] = 3, ["meta"] = { ["inventory"] = {  }, ["fields"] = {  } }, ["param2"] = 0, ["param1"] = 0 }, { ["y"] = -6, ["x"] = 0, ["name"] = "default:dirt", ["z"] = 4, ["meta"] = { ["inventory"] = {  }, ["fields"] = {  } }, ["param2"] = 0, ["param1"] = 0 }, { ["y"] = -6, ["x"] = 0, ["name"] = "default:dirt", ["z"] = 5, ["meta"] = { ["inventory"] = {  }, ["fields"] = {  } }, ["param2"] = 0, ["param1"] = 0 }, { ["y"] = -5, ["x"] = 0, ["name"] = "default:dirt", ["z"] = -6, ["meta"] = { ["inventory"] = {  }, ["fields"] = {  } }, ["param2"] = 0, ["param1"] = 0 }, { ["y"] = -5, ["x"] = 0, ["name"] = "default:dirt", ["z"] = -5, ["meta"] = { ["inventory"] = {  }, ["fields"] = {  } }, ["param2"] = 0, ["param1"] = 0 }, { ["y"] = -5, ["x"] = 0, ["name"] = "default:dirt", ["z"] = -4, ["meta"] = { ["inventory"] = {  }, ["fields"] = {  } }, ["param2"] = 0, ["param1"] = 0 }, { ["y"] = -5, ["x"] = 0, ["name"] = "default:dirt", ["z"] = -3, ["meta"] = { ["inventory"] = {  }, ["fields"] = {  } }, ["param2"] = 0, ["param1"] = 0 }, { ["y"] = -5, ["x"] = 0, ["name"] = "default:dirt", ["z"] = -2, ["meta"] = { ["inventory"] = {  }, ["fields"] = {  } }, ["param2"] = 0, ["param1"] = 0 }, { ["y"] = -5, ["x"] = 0, ["name"] = "default:dirt", ["z"] = -1, ["meta"] = { ["inventory"] = {  }, ["fields"] = {  } }, ["param2"] = 0, ["param1"] = 0 }, { ["y"] = -5, ["x"] = 0, ["name"] = "default:dirt", ["z"] = 0, ["meta"] = { ["inventory"] = {  }, ["fields"] = {  } }, ["param2"] = 0, ["param1"] = 0 }, { ["y"] = -5, ["x"] = 0, ["name"] = "default:dirt", ["z"] = 1, ["meta"] = { ["inventory"] = {  }, ["fields"] = {  } }, ["param2"] = 0, ["param1"] = 0 }, { ["y"] = -5, ["x"] = 0, ["name"] = "default:dirt", ["z"] = 2, ["meta"] = { ["inventory"] = {  }, ["fields"] = {  } }, ["param2"] = 0, ["param1"] = 0 }, { ["y"] = -5, ["x"] = 0, ["name"] = "default:dirt", ["z"] = 3, ["meta"] = { ["inventory"] = {  }, ["fields"] = {  } }, ["param2"] = 0, ["param1"] = 0 }, { ["y"] = -5, ["x"] = 0, ["name"] = "default:dirt", ["z"] = 4, ["meta"] = { ["inventory"] = {  }, ["fields"] = {  } }, ["param2"] = 0, ["param1"] = 0 }, { ["y"] = -5, ["x"] = 0, ["name"] = "default:dirt", ["z"] = 5, ["meta"] = { ["inventory"] = {  }, ["fields"] = {  } }, ["param2"] = 0, ["param1"] = 0 }, { ["y"] = -4, ["x"] = 0, ["name"] = "default:dirt", ["z"] = -6, ["meta"] = { ["inventory"] = {  }, ["fields"] = {  } }, ["param2"] = 0, ["param1"] = 0 }, { ["y"] = -4, ["x"] = 0, ["name"] = "default:dirt", ["z"] = -5, ["meta"] = { ["inventory"] = {  }, ["fields"] = {  } }, ["param2"] = 0, ["param1"] = 0 }, { ["y"] = -4, ["x"] = 0, ["name"] = "default:dirt", ["z"] = -4, ["meta"] = { ["inventory"] = {  }, ["fields"] = {  } }, ["param2"] = 0, ["param1"] = 0 }, { ["y"] = -4, ["x"] = 0, ["name"] = "default:dirt", ["z"] = -3, ["meta"] = { ["inventory"] = {  }, ["fields"] = {  } }, ["param2"] = 0, ["param1"] = 0 }, { ["y"] = -4, ["x"] = 0, ["name"] = "default:dirt", ["z"] = -2, ["meta"] = { ["inventory"] = {  }, ["fields"] = {  } }, ["param2"] = 0, ["param1"] = 0 }, { ["y"] = -4, ["x"] = 0, ["name"] = "default:dirt", ["z"] = -1, ["meta"] = { ["inventory"] = {  }, ["fields"] = {  } }, ["param2"] = 0, ["param1"] = 0 }, { ["y"] = -4, ["x"] = 0, ["name"] = "default:dirt", ["z"] = 0, ["meta"] = { ["inventory"] = {  }, ["fields"] = {  } }, ["param2"] = 0, ["param1"] = 0 }, { ["y"] = -4, ["x"] = 0, ["name"] = "default:dirt", ["z"] = 1, ["meta"] = { ["inventory"] = {  }, ["fields"] = {  } }, ["param2"] = 0, ["param1"] = 0 }, { ["y"] = -4, ["x"] = 0, ["name"] = "default:dirt", ["z"] = 2, ["meta"] = { ["inventory"] = {  }, ["fields"] = {  } }, ["param2"] = 0, ["param1"] = 0 }, { ["y"] = -4, ["x"] = 0, ["name"] = "default:dirt", ["z"] = 3, ["meta"] = { ["inventory"] = {  }, ["fields"] = {  } }, ["param2"] = 0, ["param1"] = 0 }, { ["y"] = -4, ["x"] = 0, ["name"] = "default:dirt", ["z"] = 4, ["meta"] = { ["inventory"] = {  }, ["fields"] = {  } }, ["param2"] = 0, ["param1"] = 0 }, { ["y"] = -4, ["x"] = 0, ["name"] = "default:dirt", ["z"] = 5, ["meta"] = { ["inventory"] = {  }, ["fields"] = {  } }, ["param2"] = 0, ["param1"] = 0 }, { ["y"] = -3, ["x"] = 0, ["name"] = "default:dirt", ["z"] = -6, ["meta"] = { ["inventory"] = {  }, ["fields"] = {  } }, ["param2"] = 0, ["param1"] = 0 }, { ["y"] = -3, ["x"] = 0, ["name"] = "default:dirt", ["z"] = -5, ["meta"] = { ["inventory"] = {  }, ["fields"] = {  } }, ["param2"] = 0, ["param1"] = 0 }, { ["y"] = -3, ["x"] = 0, ["name"] = "default:dirt", ["z"] = -4, ["meta"] = { ["inventory"] = {  }, ["fields"] = {  } }, ["param2"] = 0, ["param1"] = 0 }, { ["y"] = -3, ["x"] = 0, ["name"] = "default:dirt", ["z"] = -3, ["meta"] = { ["inventory"] = {  }, ["fields"] = {  } }, ["param2"] = 0, ["param1"] = 0 }, { ["y"] = -3, ["x"] = 0, ["name"] = "default:dirt", ["z"] = -2, ["meta"] = { ["inventory"] = {  }, ["fields"] = {  } }, ["param2"] = 0, ["param1"] = 0 }, { ["y"] = -3, ["x"] = 0, ["name"] = "default:dirt", ["z"] = -1, ["meta"] = { ["inventory"] = {  }, ["fields"] = {  } }, ["param2"] = 0, ["param1"] = 0 }, { ["y"] = -3, ["x"] = 0, ["name"] = "default:dirt", ["z"] = 0, ["meta"] = { ["inventory"] = {  }, ["fields"] = {  } }, ["param2"] = 0, ["param1"] = 0 }, { ["y"] = -3, ["x"] = 0, ["name"] = "default:dirt", ["z"] = 1, ["meta"] = { ["inventory"] = {  }, ["fields"] = {  } }, ["param2"] = 0, ["param1"] = 0 }, { ["y"] = -3, ["x"] = 0, ["name"] = "default:dirt", ["z"] = 2, ["meta"] = { ["inventory"] = {  }, ["fields"] = {  } }, ["param2"] = 0, ["param1"] = 0 }, { ["y"] = -3, ["x"] = 0, ["name"] = "default:dirt", ["z"] = 3, ["meta"] = { ["inventory"] = {  }, ["fields"] = {  } }, ["param2"] = 0, ["param1"] = 0 }, { ["y"] = -3, ["x"] = 0, ["name"] = "default:dirt", ["z"] = 4, ["meta"] = { ["inventory"] = {  }, ["fields"] = {  } }, ["param2"] = 0, ["param1"] = 0 }, { ["y"] = -3, ["x"] = 0, ["name"] = "default:dirt", ["z"] = 5, ["meta"] = { ["inventory"] = {  }, ["fields"] = {  } }, ["param2"] = 0, ["param1"] = 0 }, { ["y"] = -2, ["x"] = 0, ["name"] = "default:dirt", ["z"] = -6, ["meta"] = { ["inventory"] = {  }, ["fields"] = {  } }, ["param2"] = 0, ["param1"] = 0 }, { ["y"] = -2, ["x"] = 0, ["name"] = "default:dirt", ["z"] = -5, ["meta"] = { ["inventory"] = {  }, ["fields"] = {  } }, ["param2"] = 0, ["param1"] = 0 }, { ["y"] = -2, ["x"] = 0, ["name"] = "default:dirt", ["z"] = -4, ["meta"] = { ["inventory"] = {  }, ["fields"] = {  } }, ["param2"] = 0, ["param1"] = 0 }, { ["y"] = -2, ["x"] = 0, ["name"] = "default:dirt", ["z"] = -3, ["meta"] = { ["inventory"] = {  }, ["fields"] = {  } }, ["param2"] = 0, ["param1"] = 0 }, { ["y"] = -2, ["x"] = 0, ["name"] = "default:dirt", ["z"] = -2, ["meta"] = { ["inventory"] = {  }, ["fields"] = {  } }, ["param2"] = 0, ["param1"] = 0 }, { ["y"] = -2, ["x"] = 0, ["name"] = "default:dirt", ["z"] = -1, ["meta"] = { ["inventory"] = {  }, ["fields"] = {  } }, ["param2"] = 0, ["param1"] = 0 }, { ["y"] = -2, ["x"] = 0, ["name"] = "default:dirt", ["z"] = 0, ["meta"] = { ["inventory"] = {  }, ["fields"] = {  } }, ["param2"] = 0, ["param1"] = 0 }, { ["y"] = -2, ["x"] = 0, ["name"] = "default:dirt", ["z"] = 1, ["meta"] = { ["inventory"] = {  }, ["fields"] = {  } }, ["param2"] = 0, ["param1"] = 0 }, { ["y"] = -2, ["x"] = 0, ["name"] = "default:dirt", ["z"] = 2, ["meta"] = { ["inventory"] = {  }, ["fields"] = {  } }, ["param2"] = 0, ["param1"] = 0 }, { ["y"] = -2, ["x"] = 0, ["name"] = "default:dirt", ["z"] = 3, ["meta"] = { ["inventory"] = {  }, ["fields"] = {  } }, ["param2"] = 0, ["param1"] = 0 }, { ["y"] = -2, ["x"] = 0, ["name"] = "default:dirt", ["z"] = 4, ["meta"] = { ["inventory"] = {  }, ["fields"] = {  } }, ["param2"] = 0, ["param1"] = 0 }, { ["y"] = -2, ["x"] = 0, ["name"] = "default:dirt", ["z"] = 5, ["meta"] = { ["inventory"] = {  }, ["fields"] = {  } }, ["param2"] = 0, ["param1"] = 0 }, { ["y"] = -1, ["x"] = 0, ["name"] = "default:dirt", ["z"] = -6, ["meta"] = { ["inventory"] = {  }, ["fields"] = {  } }, ["param2"] = 0, ["param1"] = 0 }, { ["y"] = -1, ["x"] = 0, ["name"] = "default:dirt", ["z"] = -5, ["meta"] = { ["inventory"] = {  }, ["fields"] = {  } }, ["param2"] = 0, ["param1"] = 0 }, { ["y"] = -1, ["x"] = 0, ["name"] = "default:dirt", ["z"] = -4, ["meta"] = { ["inventory"] = {  }, ["fields"] = {  } }, ["param2"] = 0, ["param1"] = 0 }, { ["y"] = -1, ["x"] = 0, ["name"] = "default:dirt", ["z"] = -3, ["meta"] = { ["inventory"] = {  }, ["fields"] = {  } }, ["param2"] = 0, ["param1"] = 0 }, { ["y"] = -1, ["x"] = 0, ["name"] = "default:dirt", ["z"] = -2, ["meta"] = { ["inventory"] = {  }, ["fields"] = {  } }, ["param2"] = 0, ["param1"] = 0 }, { ["y"] = -1, ["x"] = 0, ["name"] = "default:dirt", ["z"] = -1, ["meta"] = { ["inventory"] = {  }, ["fields"] = {  } }, ["param2"] = 0, ["param1"] = 0 }, { ["y"] = -1, ["x"] = 0, ["name"] = "default:dirt", ["z"] = 0, ["meta"] = { ["inventory"] = {  }, ["fields"] = {  } }, ["param2"] = 0, ["param1"] = 0 }, { ["y"] = -1, ["x"] = 0, ["name"] = "default:dirt", ["z"] = 1, ["meta"] = { ["inventory"] = {  }, ["fields"] = {  } }, ["param2"] = 0, ["param1"] = 0 }, { ["y"] = -1, ["x"] = 0, ["name"] = "default:dirt", ["z"] = 2, ["meta"] = { ["inventory"] = {  }, ["fields"] = {  } }, ["param2"] = 0, ["param1"] = 0 }, { ["y"] = -1, ["x"] = 0, ["name"] = "default:dirt", ["z"] = 3, ["meta"] = { ["inventory"] = {  }, ["fields"] = {  } }, ["param2"] = 0, ["param1"] = 0 }, { ["y"] = -1, ["x"] = 0, ["name"] = "default:dirt", ["z"] = 4, ["meta"] = { ["inventory"] = {  }, ["fields"] = {  } }, ["param2"] = 0, ["param1"] = 0 }, { ["y"] = -1, ["x"] = 0, ["name"] = "default:dirt", ["z"] = 5, ["meta"] = { ["inventory"] = {  }, ["fields"] = {  } }, ["param2"] = 0, ["param1"] = 0 }, { ["y"] = 0, ["x"] = 0, ["name"] = "default:dirt", ["z"] = -6, ["meta"] = { ["inventory"] = {  }, ["fields"] = {  } }, ["param2"] = 0, ["param1"] = 0 }, { ["y"] = 0, ["x"] = 0, ["name"] = "default:dirt", ["z"] = -5, ["meta"] = { ["inventory"] = {  }, ["fields"] = {  } }, ["param2"] = 0, ["param1"] = 0 }, { ["y"] = 0, ["x"] = 0, ["name"] = "default:dirt", ["z"] = -4, ["meta"] = { ["inventory"] = {  }, ["fields"] = {  } }, ["param2"] = 0, ["param1"] = 0 }, { ["y"] = 0, ["x"] = 0, ["name"] = "default:dirt", ["z"] = -3, ["meta"] = { ["inventory"] = {  }, ["fields"] = {  } }, ["param2"] = 0, ["param1"] = 0 }, { ["y"] = 0, ["x"] = 0, ["name"] = "default:dirt", ["z"] = -2, ["meta"] = { ["inventory"] = {  }, ["fields"] = {  } }, ["param2"] = 0, ["param1"] = 0 }, { ["y"] = 0, ["x"] = 0, ["name"] = "default:dirt", ["z"] = -1, ["meta"] = { ["inventory"] = {  }, ["fields"] = {  } }, ["param2"] = 0, ["param1"] = 0 }, { ["y"] = 0, ["x"] = 0, ["name"] = "default:dirt", ["z"] = 0, ["meta"] = { ["inventory"] = {  }, ["fields"] = {  } }, ["param2"] = 0, ["param1"] = 0 }, { ["y"] = 0, ["x"] = 0, ["name"] = "default:dirt", ["z"] = 1, ["meta"] = { ["inventory"] = {  }, ["fields"] = {  } }, ["param2"] = 0, ["param1"] = 0 }, { ["y"] = 0, ["x"] = 0, ["name"] = "default:dirt", ["z"] = 2, ["meta"] = { ["inventory"] = {  }, ["fields"] = {  } }, ["param2"] = 0, ["param1"] = 0 },